Workbook
Name aa: #REF!
Name CASE: [1]코드!$K$35:$K$41
Name d: #REF!
Name DBMS: [1]코드!$G$35:$G$49
Name dd: #REF!
Name ddd: #REF!
Name dddd: #REF!
Name ddddd: #REF!
Name ddddddd: #REF!
Name dddfghsfthfsdh: #REF!
Name dddsadwed: #REF!
Name dfsdfsaf: #REF!
Name ds: #REF!
Name dsf: #REF!
Name dsfa: #REF!
Name dsfsf: #REF!
Name dssd: #REF!
Name d너뭔데: #REF!
Name ee: #REF!
Name EndUser: [1]코드!$D$35:$D$39
Name Evaluation: #REF!
Name fsafasdf: #REF!
Name HA상태: [2]코드표!$C$15:$C$16
Name HW: [1]코드!$I$35:$I$59
Name iii: #REF!
Name Language: [1]코드!$J$35:$J$61
Name LType: [1]코드!$M$35:$M$37
Name MW: [1]코드!$H$35:$H$49
Name NMS관제가능여부: [2]코드표!$C$52:$C$53
Name no: #REF!
Name OS: [1]코드!$F$35:$F$42
Name Platform: [1]코드!$L$35:$L$37
Name rr: #REF!
Name rrrr: #REF!
Name sasa: #REF!
Name SASDFSDF: #REF!
Name sddsd: #REF!
Name SDF: #REF!
Name sdkjfa: #REF!
Name sds: #REF!
Name sdsds: #REF!
Name sdsdsds: #REF!
Name sdsfa: #REF!
Name sf: #REF!
Name sfa: #REF!
Name sfasdfa: #REF!
Name sfddd: #REF!
Name sosos: #REF!
Name ss: #REF!
Name ssjsjks: #REF!
Name sss: #REF!
Name SW용도: [2]코드표!$B$88:$B$90
Name ui: #REF!
Name yes: #REF!
Name YN: '[3]점검표(재분류)'!#REF!
Name yy: #REF!
Name ㄱㄱ: #REF!
Name 가: #REF!
Name 가자: #REF!
Name 개발형태: [1]코드!$C$2:$C$7

Sheet 표지
B2: 구 분 | D2: 관리 | F2: 본 문서는 임의로 복사 되거나 배포될 수 없음 | P2: 대외비
B3: 문서번호
B10: [00]
B12: PC 취약점진단 상세결과보고서
H19: 2026.00.

Sheet 개정이력
A2: ▣ 개정이력
A4: 개정번호 | B4: 개정일자 | C4: 개정내용 | D4: 작성자 | E4: 비고
A5: v0.1 | B5: 2026. 00. 00. | C5: 최초 작성 | D5: 시큐와우

Sheet 개요
A2: 1. 목적
B3: 본 보고서는 세계사이버대학의 PC 취약점 점검 결과에 대한 보고서입니다. 따라서 본 보고서와 "보안 가이드"를 함께 참고하여 취약점이 도출된 항목에 대해 취약점을 제거 함으로써 해당 PC의 보안 강화를 목적으로 합니다.
A5: 2. 평가 정의
B6: 2.1. 취약성 평가
C7: 2.1.1. 점검항목의 중요도 및 점수 지정
C8: 점검 결과 | E8: 평가항목의 중요도
E9: 상 | G9: 중 | I9: 하
C10: 취약 (취약점 발견) | E10: 10점 | G10: 8점 | I10: 6점
C11: 양호 (취약점 제거) | E11: 0점 | G11: 0점 | I11: 0점
C12: 부분만족 (일부취약점만 제거) | E12: 5점 | G12: 4점 | I12: 3점
C14: 2.1.2. 기술적 취약점 점수 계산
D15: • 모든 취약점이 식별 되었을 경우의 점수 합(전체점수) : A
D16: • 식별된 취약점들의 점수의 점수 합(취약점수) : B
D17: • 계산식 :
D18: • 자산의 수 : N
D19: • 자산별 점수 : S1, S2, …, SN
D20: • 계산식 :
A22: 3. 취약점 제거 방안
B23: 3.1 긴급 조치 항목 우선 제거
C24: • 긴급히 조치해야할 항목으로써 우선적으로 취약점을 제거하여 주십시오.
B26: 3.2 "보안 가이드"를 참고하여 취약점 제거
C27: • 취약한 항목의 코드와 동일한 항목을 "보안가이드"에서 해당 항목에서 찾습니다.
C28: • "보안가이드"에서 해당 항목의 <조치방안>을 참고하여 시스템 환경과 서비스에 맞도록 삭제 또는 수정 등으로 취약점을 제거하여 주십시오.
C29: • <조치방안>은 해당 자산 정보에 맞춰서 참고하시기 바랍니다.

Sheet 점검대상
A2: ▣ PC 점검대상
I4: DoA | J4: 7
A5: No | B5: 자산정보 | F5: 자산평가 | J5: 비고
B6: HostName | C6: O/S | D6: IP | E6: 용도 | F6: C | G6: I | H6: A | I6: 등급
A7: =HYPERLINK("[" & MID(CELL("filename"),SEARCH("[",CELL("filename"))+1, SEARCH("]",CELL("filename"))-SEARCH("[",CELL("filename"))-1) & "]'요약 통계'!" & ADDRESS(4,ROW()+5,1,TRUE),ROW()-6) | B7: test_DBMS | C7: Ubuntu 20.04.6 LTS | D7: 192.168.1.14 | E7: 학사관리서버 | F7: 3 | G7: 3 | H7: 3 | I7: =IF(AND(SUM(F7:H7)>=8, SUM(F7:H7)<=9), "1등급", IF(AND(SUM(F7:H7)>=6, SUM(F7:H7)<=7), "2등급", IF(AND(SUM(F7:H7)>=3, SUM(F7:H7)<=5), "3등급", "")))

Sheet 요약 통계
A2: ▣ PC 점검 요약 통계
A4: 구분 | D4: 중요도 | E4: 점수 | F4: 점검통계 | L4: =HYPERLINK("[" & MID(CELL("filename"),SEARCH("[",CELL("filename"))+1, SEARCH("]",CELL("filename"))-SEARCH("[",CELL("filename"))-1) & "]'" & INDIRECT(ADDRESS(COLUMN()-5,2,1,TRUE,"점검대상")) & "'!A1",INDIRECT(ADDRESS(COLUMN()-5,2,1,TRUE,"점검대상")))
A5: 분류 | B5: 항목코드 | C5: 점검 항목 | F5: 전체항목 | G5: 점검항목 | H5: 양호 | I5: 취약 | J5: 부분만족 | K5: 해당없음
A6: 계정 관리 | B6: PC-01 | C6: 비밀번호의 주기적 변경 | D6: 상 | E6: =IF(D6="상",10,IF(D6="중",8,6)) | F6: =COUNTA($L6:INDIRECT(ADDRESS(ROW(),MATCH("",$4:$4,-1),1,1))) | G6: =F6-K6 | H6: =COUNTIF($L6:INDIRECT(ADDRESS(ROW(),MATCH("",$4:$4,-1),1,1)),H$5) | I6: =COUNTIF($L6:INDIRECT(ADDRESS(ROW(),MATCH("",$4:$4,-1),1,1)),I$5) | J6: =COUNTIF($L6:INDIRECT(ADDRESS(ROW(),MATCH("",$4:$4,-1),1,1)),J$5) | K6: =COUNTIF($L6:INDIRECT(ADDRESS(ROW(),MATCH("",$4:$4,-1),1,1)),"N/A") | L6: =IFERROR(INDIRECT(ADDRESS(ROW()+22,15,1,TRUE,L$4)),"")
B7: PC-02 | C7: 비밀번호 관리정책 설정 | D7: 상 | E7: =IF(D7="상",10,IF(D7="중",8,6)) | F7: =COUNTA($L7:INDIRECT(ADDRESS(ROW(),MATCH("",$4:$4,-1),1,1))) | G7: =F7-K7 | H7: =COUNTIF($L7:INDIRECT(ADDRESS(ROW(),MATCH("",$4:$4,-1),1,1)),H$5) | I7: =COUNTIF($L7:INDIRECT(ADDRESS(ROW(),MATCH("",$4:$4,-1),1,1)),I$5) | J7: =COUNTIF($L7:INDIRECT(ADDRESS(ROW(),MATCH("",$4:$4,-1),1,1)),J$5) | K7: =COUNTIF($L7:INDIRECT(ADDRESS(ROW(),MATCH("",$4:$4,-1),1,1)),"N/A") | L7: =IFERROR(INDIRECT(ADDRESS(ROW()+22,15,1,TRUE,L$4)),"")
B8: PC-03 | C8: 복구 콘솔에서 자동 로그온을 금지하도록 설정 | D8: 중 | E8: =IF(D8="상",10,IF(D8="중",8,6)) | F8: =COUNTA($L8:INDIRECT(ADDRESS(ROW(),MATCH("",$4:$4,-1),1,1))) | G8: =F8-K8 | H8: =COUNTIF($L8:INDIRECT(ADDRESS(ROW(),MATCH("",$4:$4,-1),1,1)),H$5) | I8: =COUNTIF($L8:INDIRECT(ADDRESS(ROW(),MATCH("",$4:$4,-1),1,1)),I$5) | J8: =COUNTIF($L8:INDIRECT(ADDRESS(ROW(),MATCH("",$4:$4,-1),1,1)),J$5) | K8: =COUNTIF($L8:INDIRECT(ADDRESS(ROW(),MATCH("",$4:$4,-1),1,1)),"N/A") | L8: =IFERROR(INDIRECT(ADDRESS(ROW()+22,15,1,TRUE,L$4)),"")
A9: 접근 관리 | B9: PC-04 | C9: 공유 폴더 제거 | D9: 상 | E9: =IF(D9="상",10,IF(D9="중",8,6)) | F9: =COUNTA($L9:INDIRECT(ADDRESS(ROW(),MATCH("",$4:$4,-1),1,1))) | G9: =F9-K9 | H9: =COUNTIF($L9:INDIRECT(ADDRESS(ROW(),MATCH("",$4:$4,-1),1,1)),H$5) | I9: =COUNTIF($L9:INDIRECT(ADDRESS(ROW(),MATCH("",$4:$4,-1),1,1)),I$5) | J9: =COUNTIF($L9:INDIRECT(ADDRESS(ROW(),MATCH("",$4:$4,-1),1,1)),J$5) | K9: =COUNTIF($L9:INDIRECT(ADDRESS(ROW(),MATCH("",$4:$4,-1),1,1)),"N/A") | L9: =IFERROR(INDIRECT(ADDRESS(ROW()+22,15,1,TRUE,L$4)),"")
B10: PC-05 | C10: 불필요한 서비스 제거 | D10: 상 | E10: =IF(D10="상",10,IF(D10="중",8,6)) | F10: =COUNTA($L10:INDIRECT(ADDRESS(ROW(),MATCH("",$4:$4,-1),1,1))) | G10: =F10-K10 | H10: =COUNTIF($L10:INDIRECT(ADDRESS(ROW(),MATCH("",$4:$4,-1),1,1)),H$5) | I10: =COUNTIF($L10:INDIRECT(ADDRESS(ROW(),MATCH("",$4:$4,-1),1,1)),I$5) | J10: =COUNTIF($L10:INDIRECT(ADDRESS(ROW(),MATCH("",$4:$4,-1),1,1)),J$5) | K10: =COUNTIF($L10:INDIRECT(ADDRESS(ROW(),MATCH("",$4:$4,-1),1,1)),"N/A") | L10: =IFERROR(INDIRECT(ADDRESS(ROW()+22,15,1,TRUE,L$4)),"")
B11: PC-06 | C11: 비인가 상용 메신저 사용 금지 | D11: 하 | E11: =IF(D11="상",10,IF(D11="중",8,6)) | F11: =COUNTA($L11:INDIRECT(ADDRESS(ROW(),MATCH("",$4:$4,-1),1,1))) | G11: =F11-K11 | H11: =COUNTIF($L11:INDIRECT(ADDRESS(ROW(),MATCH("",$4:$4,-1),1,1)),H$5) | I11: =COUNTIF($L11:INDIRECT(ADDRESS(ROW(),MATCH("",$4:$4,-1),1,1)),I$5) | J11: =COUNTIF($L11:INDIRECT(ADDRESS(ROW(),MATCH("",$4:$4,-1),1,1)),J$5) | K11: =COUNTIF($L11:INDIRECT(ADDRESS(ROW(),MATCH("",$4:$4,-1),1,1)),"N/A") | L11: =IFERROR(INDIRECT(ADDRESS(ROW()+22,15,1,TRUE,L$4)),"")
B12: PC-07 | C12: 파일 시스템이 NTFS 포맷으로 설정 | D12: 상 | E12: =IF(D12="상",10,IF(D12="중",8,6)) | F12: =COUNTA($L12:INDIRECT(ADDRESS(ROW(),MATCH("",$4:$4,-1),1,1))) | G12: =F12-K12 | H12: =COUNTIF($L12:INDIRECT(ADDRESS(ROW(),MATCH("",$4:$4,-1),1,1)),H$5) | I12: =COUNTIF($L12:INDIRECT(ADDRESS(ROW(),MATCH("",$4:$4,-1),1,1)),I$5) | J12: =COUNTIF($L12:INDIRECT(ADDRESS(ROW(),MATCH("",$4:$4,-1),1,1)),J$5) | K12: =COUNTIF($L12:INDIRECT(ADDRESS(ROW(),MATCH("",$4:$4,-1),1,1)),"N/A") | L12: =IFERROR(INDIRECT(ADDRESS(ROW()+22,15,1,TRUE,L$4)),"")
B13: PC-08 | C13: PC 내 하나의 OS만 설치(멀티 부팅 미사용) | D13: 중 | E13: =IF(D13="상",10,IF(D13="중",8,6)) | F13: =COUNTA($L13:INDIRECT(ADDRESS(ROW(),MATCH("",$4:$4,-1),1,1))) | G13: =F13-K13 | H13: =COUNTIF($L13:INDIRECT(ADDRESS(ROW(),MATCH("",$4:$4,-1),1,1)),H$5) | I13: =COUNTIF($L13:INDIRECT(ADDRESS(ROW(),MATCH("",$4:$4,-1),1,1)),I$5) | J13: =COUNTIF($L13:INDIRECT(ADDRESS(ROW(),MATCH("",$4:$4,-1),1,1)),J$5) | K13: =COUNTIF($L13:INDIRECT(ADDRESS(ROW(),MATCH("",$4:$4,-1),1,1)),"N/A") | L13: =IFERROR(INDIRECT(ADDRESS(ROW()+22,15,1,TRUE,L$4)),"")
B14: PC-09 | C14: 브라우저 종료 시 임시 인터넷 파일 폴더의 내용을 삭제하도록 설정 | D14: 중 | E14: =IF(D14="상",10,IF(D14="중",8,6)) | F14: =COUNTA($L14:INDIRECT(ADDRESS(ROW(),MATCH("",$4:$4,-1),1,1))) | G14: =F14-K14 | H14: =COUNTIF($L14:INDIRECT(ADDRESS(ROW(),MATCH("",$4:$4,-1),1,1)),H$5) | I14: =COUNTIF($L14:INDIRECT(ADDRESS(ROW(),MATCH("",$4:$4,-1),1,1)),I$5) | J14: =COUNTIF($L14:INDIRECT(ADDRESS(ROW(),MATCH("",$4:$4,-1),1,1)),J$5) | K14: =COUNTIF($L14:INDIRECT(ADDRESS(ROW(),MATCH("",$4:$4,-1),1,1)),"N/A") | L14: =IFERROR(INDIRECT(ADDRESS(ROW()+22,15,1,TRUE,L$4)),"")
A15: 패치 관리 | B15: PC-10 | C15: 주기적 보안 패치 및 벤더 권고사항 적용 | D15: 상 | E15: =IF(D15="상",10,IF(D15="중",8,6)) | F15: =COUNTA($L15:INDIRECT(ADDRESS(ROW(),MATCH("",$4:$4,-1),1,1))) | G15: =F15-K15 | H15: =COUNTIF($L15:INDIRECT(ADDRESS(ROW(),MATCH("",$4:$4,-1),1,1)),H$5) | I15: =COUNTIF($L15:INDIRECT(ADDRESS(ROW(),MATCH("",$4:$4,-1),1,1)),I$5) | J15: =COUNTIF($L15:INDIRECT(ADDRESS(ROW(),MATCH("",$4:$4,-1),1,1)),J$5) | K15: =COUNTIF($L15:INDIRECT(ADDRESS(ROW(),MATCH("",$4:$4,-1),1,1)),"N/A") | L15: =IFERROR(INDIRECT(ADDRESS(ROW()+22,15,1,TRUE,L$4)),"")
B16: PC-11 | C16: 지원이 종료되지 않은 Windows OS Build 적용 | D16: 상 | E16: =IF(D16="상",10,IF(D16="중",8,6)) | F16: =COUNTA($L16:INDIRECT(ADDRESS(ROW(),MATCH("",$4:$4,-1),1,1))) | G16: =F16-K16 | H16: =COUNTIF($L16:INDIRECT(ADDRESS(ROW(),MATCH("",$4:$4,-1),1,1)),H$5) | I16: =COUNTIF($L16:INDIRECT(ADDRESS(ROW(),MATCH("",$4:$4,-1),1,1)),I$5) | J16: =COUNTIF($L16:INDIRECT(ADDRESS(ROW(),MATCH("",$4:$4,-1),1,1)),J$5) | K16: =COUNTIF($L16:INDIRECT(ADDRESS(ROW(),MATCH("",$4:$4,-1),1,1)),"N/A") | L16: =IFERROR(INDIRECT(ADDRESS(ROW()+22,15,1,TRUE,L$4)),"")
A17: 보안 관리 | B17: PC-12 | C17: Windows 자동 로그인 점검 | D17: 상 | E17: =IF(D17="상",10,IF(D17="중",8,6)) | F17: =COUNTA($L17:INDIRECT(ADDRESS(ROW(),MATCH("",$4:$4,-1),1,1))) | G17: =F17-K17 | H17: =COUNTIF($L17:INDIRECT(ADDRESS(ROW(),MATCH("",$4:$4,-1),1,1)),H$5) | I17: =COUNTIF($L17:INDIRECT(ADDRESS(ROW(),MATCH("",$4:$4,-1),1,1)),I$5) | J17: =COUNTIF($L17:INDIRECT(ADDRESS(ROW(),MATCH("",$4:$4,-1),1,1)),J$5) | K17: =COUNTIF($L17:INDIRECT(ADDRESS(ROW(),MATCH("",$4:$4,-1),1,1)),"N/A") | L17: =IFERROR(INDIRECT(ADDRESS(ROW()+22,15,1,TRUE,L$4)),"")
B18: PC-13 | C18: 바이러스 백신 프로그램 설치 및 주기적 업데이트 | D18: 상 | E18: =IF(D18="상",10,IF(D18="중",8,6)) | F18: =COUNTA($L18:INDIRECT(ADDRESS(ROW(),MATCH("",$4:$4,-1),1,1))) | G18: =F18-K18 | H18: =COUNTIF($L18:INDIRECT(ADDRESS(ROW(),MATCH("",$4:$4,-1),1,1)),H$5) | I18: =COUNTIF($L18:INDIRECT(ADDRESS(ROW(),MATCH("",$4:$4,-1),1,1)),I$5) | J18: =COUNTIF($L18:INDIRECT(ADDRESS(ROW(),MATCH("",$4:$4,-1),1,1)),J$5) | K18: =COUNTIF($L18:INDIRECT(ADDRESS(ROW(),MATCH("",$4:$4,-1),1,1)),"N/A") | L18: =IFERROR(INDIRECT(ADDRESS(ROW()+22,15,1,TRUE,L$4)),"")
B19: PC-14 | C19: 바이러스 백신 프로그램에서 제공하는 실시간 감시 기능 활성화 | D19: 상 | E19: =IF(D19="상",10,IF(D19="중",8,6)) | F19: =COUNTA($L19:INDIRECT(ADDRESS(ROW(),MATCH("",$4:$4,-1),1,1))) | G19: =F19-K19 | H19: =COUNTIF($L19:INDIRECT(ADDRESS(ROW(),MATCH("",$4:$4,-1),1,1)),H$5) | I19: =COUNTIF($L19:INDIRECT(ADDRESS(ROW(),MATCH("",$4:$4,-1),1,1)),I$5) | J19: =COUNTIF($L19:INDIRECT(ADDRESS(ROW(),MATCH("",$4:$4,-1),1,1)),J$5) | K19: =COUNTIF($L19:INDIRECT(ADDRESS(ROW(),MATCH("",$4:$4,-1),1,1)),"N/A") | L19: =IFERROR(INDIRECT(ADDRESS(ROW()+22,15,1,TRUE,L$4)),"")
B20: PC-15 | C20: OS에서 제공하는 침입차단 기능 활성화 | D20: 상 | E20: =IF(D20="상",10,IF(D20="중",8,6)) | F20: =COUNTA($L20:INDIRECT(ADDRESS(ROW(),MATCH("",$4:$4,-1),1,1))) | G20: =F20-K20 | H20: =COUNTIF($L20:INDIRECT(ADDRESS(ROW(),MATCH("",$4:$4,-1),1,1)),H$5) | I20: =COUNTIF($L20:INDIRECT(ADDRESS(ROW(),MATCH("",$4:$4,-1),1,1)),I$5) | J20: =COUNTIF($L20:INDIRECT(ADDRESS(ROW(),MATCH("",$4:$4,-1),1,1)),J$5) | K20: =COUNTIF($L20:INDIRECT(ADDRESS(ROW(),MATCH("",$4:$4,-1),1,1)),"N/A") | L20: =IFERROR(INDIRECT(ADDRESS(ROW()+22,15,1,TRUE,L$4)),"")
B21: PC-16 | C21: 화면보호기 대기 시간 설정 및 재시작 시 암호 보호 설정 | D21: 중 | E21: =IF(D21="상",10,IF(D21="중",8,6)) | F21: =COUNTA($L21:INDIRECT(ADDRESS(ROW(),MATCH("",$4:$4,-1),1,1))) | G21: =F21-K21 | H21: =COUNTIF($L21:INDIRECT(ADDRESS(ROW(),MATCH("",$4:$4,-1),1,1)),H$5) | I21: =COUNTIF($L21:INDIRECT(ADDRESS(ROW(),MATCH("",$4:$4,-1),1,1)),I$5) | J21: =COUNTIF($L21:INDIRECT(ADDRESS(ROW(),MATCH("",$4:$4,-1),1,1)),J$5) | K21: =COUNTIF($L21:INDIRECT(ADDRESS(ROW(),MATCH("",$4:$4,-1),1,1)),"N/A") | L21: =IFERROR(INDIRECT(ADDRESS(ROW()+22,15,1,TRUE,L$4)),"")
B22: PC-17 | C22: CD, DVD, USB 메모리 등 이동식 미디어의 자동 실행 방지 | D22: 상 | E22: =IF(D22="상",10,IF(D22="중",8,6)) | F22: =COUNTA($L22:INDIRECT(ADDRESS(ROW(),MATCH("",$4:$4,-1),1,1))) | G22: =F22-K22 | H22: =COUNTIF($L22:INDIRECT(ADDRESS(ROW(),MATCH("",$4:$4,-1),1,1)),H$5) | I22: =COUNTIF($L22:INDIRECT(ADDRESS(ROW(),MATCH("",$4:$4,-1),1,1)),I$5) | J22: =COUNTIF($L22:INDIRECT(ADDRESS(ROW(),MATCH("",$4:$4,-1),1,1)),J$5) | K22: =COUNTIF($L22:INDIRECT(ADDRESS(ROW(),MATCH("",$4:$4,-1),1,1)),"N/A") | L22: =IFERROR(INDIRECT(ADDRESS(ROW()+22,15,1,TRUE,L$4)),"")
B23: PC-18 | C23: 원격 지원을 금지하도록 정책이 설정 | D23: 중 | E23: =IF(D23="상",10,IF(D23="중",8,6)) | F23: =COUNTA($L23:INDIRECT(ADDRESS(ROW(),MATCH("",$4:$4,-1),1,1))) | G23: =F23-K23 | H23: =COUNTIF($L23:INDIRECT(ADDRESS(ROW(),MATCH("",$4:$4,-1),1,1)),H$5) | I23: =COUNTIF($L23:INDIRECT(ADDRESS(ROW(),MATCH("",$4:$4,-1),1,1)),I$5) | J23: =COUNTIF($L23:INDIRECT(ADDRESS(ROW(),MATCH("",$4:$4,-1),1,1)),J$5) | K23: =COUNTIF($L23:INDIRECT(ADDRESS(ROW(),MATCH("",$4:$4,-1),1,1)),"N/A") | L23: =IFERROR(INDIRECT(ADDRESS(ROW()+22,15,1,TRUE,L$4)),"")
E24: =IF(D24="상",10,IF(D24="중",8,6)) | F24: =COUNTA($L24:INDIRECT(ADDRESS(ROW(),MATCH("",$4:$4,-1),1,1))) | G24: =F24-K24 | H24: =COUNTIF($L24:INDIRECT(ADDRESS(ROW(),MATCH("",$4:$4,-1),1,1)),H$5) | I24: =COUNTIF($L24:INDIRECT(ADDRESS(ROW(),MATCH("",$4:$4,-1),1,1)),I$5) | J24: =COUNTIF($L24:INDIRECT(ADDRESS(ROW(),MATCH("",$4:$4,-1),1,1)),J$5) | K24: =COUNTIF($L24:INDIRECT(ADDRESS(ROW(),MATCH("",$4:$4,-1),1,1)),"N/A") | L24: =IFERROR(INDIRECT(ADDRESS(ROW()+22,15,1,TRUE,L$4)),"")
E25: =IF(D25="상",10,IF(D25="중",8,6)) | F25: =COUNTA($L25:INDIRECT(ADDRESS(ROW(),MATCH("",$4:$4,-1),1,1))) | G25: =F25-K25 | H25: =COUNTIF($L25:INDIRECT(ADDRESS(ROW(),MATCH("",$4:$4,-1),1,1)),H$5) | I25: =COUNTIF($L25:INDIRECT(ADDRESS(ROW(),MATCH("",$4:$4,-1),1,1)),I$5) | J25: =COUNTIF($L25:INDIRECT(ADDRESS(ROW(),MATCH("",$4:$4,-1),1,1)),J$5) | K25: =COUNTIF($L25:INDIRECT(ADDRESS(ROW(),MATCH("",$4:$4,-1),1,1)),"N/A") | L25: =IFERROR(INDIRECT(ADDRESS(ROW()+22,15,1,TRUE,L$4)),"")
E26: =IF(D26="상",10,IF(D26="중",8,6)) | F26: =COUNTA($L26:INDIRECT(ADDRESS(ROW(),MATCH("",$4:$4,-1),1,1))) | G26: =F26-K26 | H26: =COUNTIF($L26:INDIRECT(ADDRESS(ROW(),MATCH("",$4:$4,-1),1,1)),H$5) | I26: =COUNTIF($L26:INDIRECT(ADDRESS(ROW(),MATCH("",$4:$4,-1),1,1)),I$5) | J26: =COUNTIF($L26:INDIRECT(ADDRESS(ROW(),MATCH("",$4:$4,-1),1,1)),J$5) | K26: =COUNTIF($L26:INDIRECT(ADDRESS(ROW(),MATCH("",$4:$4,-1),1,1)),"N/A") | L26: =IFERROR(INDIRECT(ADDRESS(ROW()+22,15,1,TRUE,L$4)),"")
E27: =IF(D27="상",10,IF(D27="중",8,6)) | F27: =COUNTA($L27:INDIRECT(ADDRESS(ROW(),MATCH("",$4:$4,-1),1,1))) | G27: =F27-K27 | H27: =COUNTIF($L27:INDIRECT(ADDRESS(ROW(),MATCH("",$4:$4,-1),1,1)),H$5) | I27: =COUNTIF($L27:INDIRECT(ADDRESS(ROW(),MATCH("",$4:$4,-1),1,1)),I$5) | J27: =COUNTIF($L27:INDIRECT(ADDRESS(ROW(),MATCH("",$4:$4,-1),1,1)),J$5) | K27: =COUNTIF($L27:INDIRECT(ADDRESS(ROW(),MATCH("",$4:$4,-1),1,1)),"N/A") | L27: =IFERROR(INDIRECT(ADDRESS(ROW()+22,15,1,TRUE,L$4)),"")
E28: =IF(D28="상",10,IF(D28="중",8,6)) | F28: =COUNTA($L28:INDIRECT(ADDRESS(ROW(),MATCH("",$4:$4,-1),1,1))) | G28: =F28-K28 | H28: =COUNTIF($L28:INDIRECT(ADDRESS(ROW(),MATCH("",$4:$4,-1),1,1)),H$5) | I28: =COUNTIF($L28:INDIRECT(ADDRESS(ROW(),MATCH("",$4:$4,-1),1,1)),I$5) | J28: =COUNTIF($L28:INDIRECT(ADDRESS(ROW(),MATCH("",$4:$4,-1),1,1)),J$5) | K28: =COUNTIF($L28:INDIRECT(ADDRESS(ROW(),MATCH("",$4:$4,-1),1,1)),"N/A") | L28: =IFERROR(INDIRECT(ADDRESS(ROW()+22,15,1,TRUE,L$4)),"")
E29: =IF(D29="상",10,IF(D29="중",8,6)) | F29: =COUNTA($L29:INDIRECT(ADDRESS(ROW(),MATCH("",$4:$4,-1),1,1))) | G29: =F29-K29 | H29: =COUNTIF($L29:INDIRECT(ADDRESS(ROW(),MATCH("",$4:$4,-1),1,1)),H$5) | I29: =COUNTIF($L29:INDIRECT(ADDRESS(ROW(),MATCH("",$4:$4,-1),1,1)),I$5) | J29: =COUNTIF($L29:INDIRECT(ADDRESS(ROW(),MATCH("",$4:$4,-1),1,1)),J$5) | K29: =COUNTIF($L29:INDIRECT(ADDRESS(ROW(),MATCH("",$4:$4,-1),1,1)),"N/A") | L29: =IFERROR(INDIRECT(ADDRESS(ROW()+22,15,1,TRUE,L$4)),"")
E30: =IF(D30="상",10,IF(D30="중",8,6)) | F30: =COUNTA($L30:INDIRECT(ADDRESS(ROW(),MATCH("",$4:$4,-1),1,1))) | G30: =F30-K30 | H30: =COUNTIF($L30:INDIRECT(ADDRESS(ROW(),MATCH("",$4:$4,-1),1,1)),H$5) | I30: =COUNTIF($L30:INDIRECT(ADDRESS(ROW(),MATCH("",$4:$4,-1),1,1)),I$5) | J30: =COUNTIF($L30:INDIRECT(ADDRESS(ROW(),MATCH("",$4:$4,-1),1,1)),J$5) | K30: =COUNTIF($L30:INDIRECT(ADDRESS(ROW(),MATCH("",$4:$4,-1),1,1)),"N/A") | L30: =IFERROR(INDIRECT(ADDRESS(ROW()+22,15,1,TRUE,L$4)),"")
E31: =IF(D31="상",10,IF(D31="중",8,6)) | F31: =COUNTA($L31:INDIRECT(ADDRESS(ROW(),MATCH("",$4:$4,-1),1,1))) | G31: =F31-K31 | H31: =COUNTIF($L31:INDIRECT(ADDRESS(ROW(),MATCH("",$4:$4,-1),1,1)),H$5) | I31: =COUNTIF($L31:INDIRECT(ADDRESS(ROW(),MATCH("",$4:$4,-1),1,1)),I$5) | J31: =COUNTIF($L31:INDIRECT(ADDRESS(ROW(),MATCH("",$4:$4,-1),1,1)),J$5) | K31: =COUNTIF($L31:INDIRECT(ADDRESS(ROW(),MATCH("",$4:$4,-1),1,1)),"N/A") | L31: =IFERROR(INDIRECT(ADDRESS(ROW()+22,15,1,TRUE,L$4)),"")
E32: =IF(D32="상",10,IF(D32="중",8,6)) | F32: =COUNTA($L32:INDIRECT(ADDRESS(ROW(),MATCH("",$4:$4,-1),1,1))) | G32: =F32-K32 | H32: =COUNTIF($L32:INDIRECT(ADDRESS(ROW(),MATCH("",$4:$4,-1),1,1)),H$5) | I32: =COUNTIF($L32:INDIRECT(ADDRESS(ROW(),MATCH("",$4:$4,-1),1,1)),I$5) | J32: =COUNTIF($L32:INDIRECT(ADDRESS(ROW(),MATCH("",$4:$4,-1),1,1)),J$5) | K32: =COUNTIF($L32:INDIRECT(ADDRESS(ROW(),MATCH("",$4:$4,-1),1,1)),"N/A") | L32: =IFERROR(INDIRECT(ADDRESS(ROW()+22,15,1,TRUE,L$4)),"")
E33: =IF(D33="상",10,IF(D33="중",8,6)) | F33: =COUNTA($L33:INDIRECT(ADDRESS(ROW(),MATCH("",$4:$4,-1),1,1))) | G33: =F33-K33 | H33: =COUNTIF($L33:INDIRECT(ADDRESS(ROW(),MATCH("",$4:$4,-1),1,1)),H$5) | I33: =COUNTIF($L33:INDIRECT(ADDRESS(ROW(),MATCH("",$4:$4,-1),1,1)),I$5) | J33: =COUNTIF($L33:INDIRECT(ADDRESS(ROW(),MATCH("",$4:$4,-1),1,1)),J$5) | K33: =COUNTIF($L33:INDIRECT(ADDRESS(ROW(),MATCH("",$4:$4,-1),1,1)),"N/A") | L33: =IFERROR(INDIRECT(ADDRESS(ROW()+22,15,1,TRUE,L$4)),"")
E34: =IF(D34="상",10,IF(D34="중",8,6)) | F34: =COUNTA($L34:INDIRECT(ADDRESS(ROW(),MATCH("",$4:$4,-1),1,1))) | G34: =F34-K34 | H34: =COUNTIF($L34:INDIRECT(ADDRESS(ROW(),MATCH("",$4:$4,-1),1,1)),H$5) | I34: =COUNTIF($L34:INDIRECT(ADDRESS(ROW(),MATCH("",$4:$4,-1),1,1)),I$5) | J34: =COUNTIF($L34:INDIRECT(ADDRESS(ROW(),MATCH("",$4:$4,-1),1,1)),J$5) | K34: =COUNTIF($L34:INDIRECT(ADDRESS(ROW(),MATCH("",$4:$4,-1),1,1)),"N/A") | L34: =IFERROR(INDIRECT(ADDRESS(ROW()+22,15,1,TRUE,L$4)),"")
E35: =IF(D35="상",10,IF(D35="중",8,6)) | F35: =COUNTA($L35:INDIRECT(ADDRESS(ROW(),MATCH("",$4:$4,-1),1,1))) | G35: =F35-K35 | H35: =COUNTIF($L35:INDIRECT(ADDRESS(ROW(),MATCH("",$4:$4,-1),1,1)),H$5) | I35: =COUNTIF($L35:INDIRECT(ADDRESS(ROW(),MATCH("",$4:$4,-1),1,1)),I$5) | J35: =COUNTIF($L35:INDIRECT(ADDRESS(ROW(),MATCH("",$4:$4,-1),1,1)),J$5) | K35: =COUNTIF($L35:INDIRECT(ADDRESS(ROW(),MATCH("",$4:$4,-1),1,1)),"N/A") | L35: =IFERROR(INDIRECT(ADDRESS(ROW()+22,15,1,TRUE,L$4)),"")
... E72: =IF(D72="상",10,IF(D72="중",8,6)) | F72: =COUNTA($L72:INDIRECT(ADDRESS(ROW(),MATCH("",$4:$4,-1),1,1))) | G72: =F72-K72 | H72: =COUNTIF($L72:INDIRECT(ADDRESS(ROW(),MATCH("",$4:$4,-1),1,1)),H$5) | I72: =COUNTIF($L72:INDIRECT(ADDRESS(ROW(),MATCH("",$4:$4,-1),1,1)),I$5) | J72: =COUNTIF($L72:INDIRECT(ADDRESS(ROW(),MATCH("",$4:$4,-1),1,1)),J$5) | K72: =COUNTIF($L72:INDIRECT(ADDRESS(ROW(),MATCH("",$4:$4,-1),1,1)),"N/A") | L72: =IFERROR(INDIRECT(ADDRESS(ROW()+22,15,1,TRUE,L$4)),"")
A73: 전체항목 합계 | E73: =SUM(E6:E72) | F73: =SUM(F6:F72) | G73: =SUM(G6:G72) | H73: =SUM(H6:H72) | I73: =SUM(I6:I72) | J73: =SUM(J6:J72) | K73: =SUM(K6:K72) | L73: =COUNTIF(L6:L72,"양호")+COUNTIF(L6:L72,"취약")+COUNTIF(L6:L72,"부분만족")+COUNTIF(L6:L72,"N/A")
G75: 취약점제거 | J75: 양호 | K75: =SUM(L75:L75) | L75: =COUNTIF(L$6:L$72,$J75)
G76: 취약점발견 | J76: 취약 | K76: =SUM(L76:L76) | L76: =COUNTIF(L$6:L$72,$J76)
G77: 일부 취약점만 제거 | J77: 부분만족 | K77: =SUM(L77:L77) | L77: =COUNTIF(L$6:L$72,$J77)
G78: 해당없음 | J78: N/A | K78: =SUM(L78:L78) | L78: =COUNTIF(L$6:L$72,$J78)
I80: 상 | J80: 양호 | K80: =SUM(L80:L80) | L80: =COUNTIFS($D$6:$D$72,$I$80,L$6:L$72,$J80)
...

Sheet 보안수준 통계
A2: ▣ 점검 영역별 보안수준
A4: 구분 | C4: 점검 결과 | I4: 점검 점수
C5: 전체항목 | D5: 점검항목 | E5: 양호 | F5: 취약 | G5: 부분만족 | H5: 해당없음 | I5: 전체점수 | J5: 취약점수 | K5: 보안수준
A6: 계정 관리 | C6: =SUM('sample:기준 DB'!D18) | D6: =SUM('sample:기준 DB'!E18) | E6: =SUM('sample:기준 DB'!F18) | F6: =SUM('sample:기준 DB'!G18) | G6: =SUM('sample:기준 DB'!H18) | H6: =SUM('sample:기준 DB'!I18) | I6: =SUM('sample:기준 DB'!J18) | J6: =SUM('sample:기준 DB'!K18) | K6: =IF(I6=0,"N/A",((I6-J6)/I6)*1)
A7: 접근 관리 | C7: =SUM('sample:기준 DB'!D19) | D7: =SUM('sample:기준 DB'!E19) | E7: =SUM('sample:기준 DB'!F19) | F7: =SUM('sample:기준 DB'!G19) | G7: =SUM('sample:기준 DB'!H19) | H7: =SUM('sample:기준 DB'!I19) | I7: =SUM('sample:기준 DB'!J19) | J7: =SUM('sample:기준 DB'!K19) | K7: =IF(I7=0,"N/A",((I7-J7)/I7)*1)
A8: 패치 관리 | C8: =SUM('sample:기준 DB'!D20) | D8: =SUM('sample:기준 DB'!E20) | E8: =SUM('sample:기준 DB'!F20) | F8: =SUM('sample:기준 DB'!G20) | G8: =SUM('sample:기준 DB'!H20) | H8: =SUM('sample:기준 DB'!I20) | I8: =SUM('sample:기준 DB'!J20) | J8: =SUM('sample:기준 DB'!K20) | K8: =IF(I8=0,"N/A",((I8-J8)/I8)*1)
A9: 보안 관리 | C9: =SUM('sample:기준 DB'!D21) | D9: =SUM('sample:기준 DB'!E21) | E9: =SUM('sample:기준 DB'!F21) | F9: =SUM('sample:기준 DB'!G21) | G9: =SUM('sample:기준 DB'!H21) | H9: =SUM('sample:기준 DB'!I21) | I9: =SUM('sample:기준 DB'!J21) | J9: =SUM('sample:기준 DB'!K21) | K9: =IF(I9=0,"N/A",((I9-J9)/I9)*1)
A10: - | C10: =SUM('sample:기준 DB'!D22) | D10: =SUM('sample:기준 DB'!E22) | E10: =SUM('sample:기준 DB'!F22) | F10: =SUM('sample:기준 DB'!G22) | G10: =SUM('sample:기준 DB'!H22) | H10: =SUM('sample:기준 DB'!I22) | I10: =SUM('sample:기준 DB'!J22) | J10: =SUM('sample:기준 DB'!K22) | K10: =IF(I10=0,"N/A",((I10-J10)/I10)*1)
A11: 계 | C11: =SUM(C6:C10) | D11: =SUM(D6:D10) | E11: =SUM(E6:E10) | F11: =SUM(F6:F10) | G11: =SUM(G6:G10) | H11: =SUM(H6:H10) | I11: =SUM(I6:I10) | J11: =SUM(J6:J10) | K11: =K37
A13: ▣ 점검 영역별 보안수준 그래프
A32: ▣ 장비별 보안수준
A34: Host 명 | C34: 점검 결과 | I34: 점검 점수
C35: 전체항목 | D35: 점검항목 | E35: 양호 | F35: 취약 | G35: 부분만족 | H35: 해당없음 | I35: 전체점수 | J35: 취약점수 | K35: 보안수준
A36: PC | B36: =INDIRECT(ADDRESS(ROW()-29,2,1,TRUE,"점검대상")) | C36: =IFERROR(INDIRECT(ADDRESS(23,COLUMN()+1,1,TRUE,$B36)),0) | D36: =IFERROR(INDIRECT(ADDRESS(23,COLUMN()+1,1,TRUE,$B36)),0) | E36: =IFERROR(INDIRECT(ADDRESS(23,COLUMN()+1,1,TRUE,$B36)),0) | F36: =IFERROR(INDIRECT(ADDRESS(23,COLUMN()+1,1,TRUE,$B36)),0) | G36: =IFERROR(INDIRECT(ADDRESS(23,COLUMN()+1,1,TRUE,$B36)),0) | H36: =IFERROR(INDIRECT(ADDRESS(23,COLUMN()+1,1,TRUE,$B36)),0) | I36: =IFERROR(INDIRECT(ADDRESS(23,COLUMN()+1,1,TRUE,$B36)),0) | J36: =IFERROR(INDIRECT(ADDRESS(23,COLUMN()+1,1,TRUE,$B36)),0) | K36: =IF(I36=0,"N/A",((I36-J36)/I36)*1)
A37: 계 | C37: =SUM(C36:C36) | D37: =SUM(D36:D36) | E37: =SUM(E36:E36) | F37: =SUM(F36:F36) | G37: =SUM(G36:G36) | H37: =SUM(H36:H36) | I37: =SUM(I36:I36) | J37: =SUM(J36:J36) | K37: =SUM(K36:K36)/(COUNTA(K36:K36)-COUNTIF(K36:K36,"N/A"))

Sheet sample
A2: ▣ 장비별 점검 상세 결과 | E2: =HYPERLINK("[" & MID(CELL("filename"),SEARCH("[",CELL("filename"))+1, SEARCH("]",CELL("filename"))-SEARCH("[",CELL("filename"))-1) & "]'" & "점검대상" & "'!A1","목 차")
A4: ▣ 시스템 현황
A6: Host Name | C6: =MID(CELL("filename",$A$1),FIND("]",CELL("filename",$A$1))+1,100) | G6: O/S | I6: =IFERROR(VLOOKUP($C$6,점검대상!$B:$I,2,FALSE),"-") | P6: ▣ 장비별 보안수준 그래프
A7: IP Address | C7: =IFERROR(VLOOKUP($C$6,점검대상!$B:$I,3,FALSE),"-") | G7: 용도 | I7: =IFERROR(VLOOKUP($C$6,점검대상!$B:$I,4,FALSE),"-")
A9: ▣ 자산평가
A11: 자산가치 | C11: C | D11: I | E11: A | F11: 중요도 | H11: 등급 | J11: DoA
C12: =IFERROR(VLOOKUP($C$6,점검대상!$B:$I,COLUMN()+2,FALSE),"-") | D12: =IFERROR(VLOOKUP($C$6,점검대상!$B:$I,COLUMN()+2,FALSE),"-") | E12: =IFERROR(VLOOKUP($C$6,점검대상!$B:$I,COLUMN()+2,FALSE),"-") | F12: =SUM(C12:E12) | H12: =IF(F12>=7,"상",IF(F12>=5,"중","하")) | J12: =점검대상!$J$4
A14: ▣ 영역별 점검 결과
A16: 분류 | D16: 항목 통계 | J16: 점검 점수
D17: 전체 | E17: 점검 | F17: 양호 | G17: 취약 | H17: 부분만족 | I17: 해당없음 | J17: 전체점수 | K17: 취약점수 | L17: 보안수준
A18: 계정 관리 | D18: 3 | E18: =$D18-I18 | F18: =COUNTIF(O28:O30,"양호") | G18: =COUNTIF(O28:O30,"취약") | H18: =COUNTIF(O28:O30,"부분만족") | I18: =COUNTIF(O28:O30,"N/A")+COUNTIF(O28:O30,"인터뷰")+COUNTIF(O28:O30,"수동점검")+COUNTIF(O28:O30,"ERROR") | J18: =SUM(M28:M30) | K18: =SUM(N28:N30) | L18: =IF(J18=0,"N/A",((J18-K18)/J18)*1)
A19: 접근 관리 | D19: 6 | E19: =$D19-I19 | F19: =COUNTIF(O31:O36,"양호") | G19: =COUNTIF(O31:O36,"취약") | H19: =COUNTIF(O31:O36,"부분만족") | I19: =COUNTIF(O31:O36,"N/A")+COUNTIF(O31:O36,"인터뷰")+COUNTIF(O31:O36,"수동점검")+COUNTIF(O31:O36,"ERROR") | J19: =SUM(M31:M36) | K19: =SUM(N31:N36) | L19: =IF(J19=0,"N/A",((J19-K19)/J19)*1)
A20: 패치 관리 | D20: 2 | E20: =$D20-I20 | F20: =COUNTIF(O37:O38,"양호") | G20: =COUNTIF(O37:O38,"취약") | H20: =COUNTIF(O37:O38,"부분만족") | I20: =COUNTIF(O37:O38,"N/A")+COUNTIF(O37:O38,"인터뷰")+COUNTIF(O37:O38,"수동점검")+COUNTIF(O37:O38,"ERROR") | J20: =SUM(M37:M38) | K20: =SUM(N37:N38) | L20: =IF(J20=0,"N/A",((J20-K20)/J20)*1)
A21: 보안 관리 | D21: 7 | E21: =$D21-I21 | F21: =COUNTIF(O39:O45,"양호") | G21: =COUNTIF(O39:O45,"취약") | H21: =COUNTIF(O39:O45,"부분만족") | I21: =COUNTIF(O39:O45,"N/A")+COUNTIF(O39:O45,"인터뷰")+COUNTIF(O39:O45,"수동점검")+COUNTIF(O39:O45,"ERROR") | J21: =SUM(M39:M45) | K21: =SUM(N39:N45) | L21: =IF(J21=0,"N/A",((J21-K21)/J21)*1)
A22: - | D22: 0 | E22: 0 | F22: 0 | G22: 0 | H22: 0 | I22: 0 | J22: 0 | K22: 0 | L22: =IF(J22=0,"N/A",((J22-K22)/J22)*1)
A23: 전체 보안 수준 | D23: 18 | E23: =SUM(E18:E22) | F23: =SUM(F18:F22) | G23: =SUM(G18:G22) | H23: =SUM(H18:H22) | I23: =SUM(I18:I22) | J23: =SUM(J18:J22) | K23: =SUM(K18:K22) | L23: =IF(J23=0,"N/A",((J23-K23)/J23)*1)
A25: ▣ 상세 점검 현황 | Q25: (취약점제거: '양호', 취약점발견: '취약', 일부 취약점만 제거: '부분만족', 해당사항없음: 'N/A')
A27: 구분 | C27: 점검 항목 | L27: 중요도 | M27: 중요도 값 | N27: 점검 결과 값 | O27: 점검결과 | P27: 점검현황 | Q27: 운영현황 | U27: 점검 현황 사항 입력 란
A28: 계정 관리 | C28: PC-01 | D28: 비밀번호의 주기적 변경 | L28: 상 | M28: =IF(L28="상", 10, IF(L28="중", 8, IF(L28="하", 6, "-"))) | N28: =IF(OR(O28="", O28="N/A"), "-", IF(O28="양호", 0, IF(O28="부분만족", M28/2, M28))) | O28: N/A | P28: =IF(O28="양호",'기준 DB'!C2&U28,IF(O28="취약",'기준 DB'!D2&V28,IF(OR(O28="N/A",O28="수동점검"),'기준 DB'!E2,"-")))
C29: PC-02 | D29: 비밀번호 관리정책 설정 | L29: 상 | M29: =IF(L29="상", 10, IF(L29="중", 8, IF(L29="하", 6, "-"))) | N29: =IF(OR(O29="", O29="N/A"), "-", IF(O29="양호", 0, IF(O29="부분만족", M29/2, M29))) | O29: N/A | P29: =IF(O29="양호",'기준 DB'!C3&U29,IF(O29="취약",'기준 DB'!D3&V29,IF(OR(O29="N/A",O29="수동점검"),'기준 DB'!E3,"-")))
C30: PC-03 | D30: 복구 콘솔에서 자동 로그온을 금지하도록 설정 | L30: 중 | M30: =IF(L30="상", 10, IF(L30="중", 8, IF(L30="하", 6, "-"))) | N30: =IF(OR(O30="", O30="N/A"), "-", IF(O30="양호", 0, IF(O30="부분만족", M30/2, M30))) | O30: N/A | P30: =IF(O30="양호",'기준 DB'!C4&U30,IF(O30="취약",'기준 DB'!D4&V30,IF(OR(O30="N/A",O30="수동점검"),'기준 DB'!E4,"-")))
A31: 접근 관리 | C31: PC-04 | D31: 공유 폴더 제거 | L31: 상 | M31: =IF(L31="상", 10, IF(L31="중", 8, IF(L31="하", 6, "-"))) | N31: =IF(OR(O31="", O31="N/A"), "-", IF(O31="양호", 0, IF(O31="부분만족", M31/2, M31))) | O31: N/A | P31: =IF(O31="양호",'기준 DB'!C5&U31,IF(O31="취약",'기준 DB'!D5&V31,IF(OR(O31="N/A",O31="수동점검"),'기준 DB'!E5,"-")))
C32: PC-05 | D32: 불필요한 서비스 제거 | L32: 상 | M32: =IF(L32="상", 10, IF(L32="중", 8, IF(L32="하", 6, "-"))) | N32: =IF(OR(O32="", O32="N/A"), "-", IF(O32="양호", 0, IF(O32="부분만족", M32/2, M32))) | O32: N/A | P32: =IF(O32="양호",'기준 DB'!C6&U32,IF(O32="취약",'기준 DB'!D6&V32,IF(OR(O32="N/A",O32="수동점검"),'기준 DB'!E6,"-")))
C33: PC-06 | D33: 비인가 상용 메신저 사용 금지 | L33: 하 | M33: =IF(L33="상", 10, IF(L33="중", 8, IF(L33="하", 6, "-"))) | N33: =IF(OR(O33="", O33="N/A"), "-", IF(O33="양호", 0, IF(O33="부분만족", M33/2, M33))) | O33: N/A | P33: =IF(O33="양호",'기준 DB'!C7&U33,IF(O33="취약",'기준 DB'!D7&V33,IF(OR(O33="N/A",O33="수동점검"),'기준 DB'!E7,"-")))
C34: PC-07 | D34: 파일 시스템이 NTFS 포맷으로 설정 | L34: 상 | M34: =IF(L34="상", 10, IF(L34="중", 8, IF(L34="하", 6, "-"))) | N34: =IF(OR(O34="", O34="N/A"), "-", IF(O34="양호", 0, IF(O34="부분만족", M34/2, M34))) | O34: N/A | P34: =IF(O34="양호",'기준 DB'!C8&U34,IF(O34="취약",'기준 DB'!D8&V34,IF(OR(O34="N/A",O34="수동점검"),'기준 DB'!E8,"-")))
C35: PC-08 | D35: PC 내 하나의 OS만 설치(멀티 부팅 미사용) | L35: 중 | M35: =IF(L35="상", 10, IF(L35="중", 8, IF(L35="하", 6, "-"))) | N35: =IF(OR(O35="", O35="N/A"), "-", IF(O35="양호", 0, IF(O35="부분만족", M35/2, M35))) | O35: N/A | P35: =IF(O35="양호",'기준 DB'!C9&U35,IF(O35="취약",'기준 DB'!D9&V35,IF(OR(O35="N/A",O35="수동점검"),'기준 DB'!E9,"-")))
C36: PC-09 | D36: 브라우저 종료 시 임시 인터넷 파일 폴더의 내용을 삭제하도록 설정 | L36: 중 | M36: =IF(L36="상", 10, IF(L36="중", 8, IF(L36="하", 6, "-"))) | N36: =IF(OR(O36="", O36="N/A"), "-", IF(O36="양호", 0, IF(O36="부분만족", M36/2, M36))) | O36: N/A | P36: =IF(O36="양호",'기준 DB'!C10&U36,IF(O36="취약",'기준 DB'!D10&V36,IF(OR(O36="N/A",O36="수동점검"),'기준 DB'!E10,"-")))
A37: 패치 관리 | C37: PC-10 | D37: 주기적 보안 패치 및 벤더 권고사항 적용 | L37: 상 | M37: =IF(L37="상", 10, IF(L37="중", 8, IF(L37="하", 6, "-"))) | N37: =IF(OR(O37="", O37="N/A"), "-", IF(O37="양호", 0, IF(O37="부분만족", M37/2, M37))) | O37: N/A | P37: =IF(O37="양호",'기준 DB'!C11&U37,IF(O37="취약",'기준 DB'!D11&V37,IF(OR(O37="N/A",O37="수동점검"),'기준 DB'!E11,"-")))
C38: PC-11 | D38: 지원이 종료되지 않은 Windows OS Build 적용 | L38: 상 | M38: =IF(L38="상", 10, IF(L38="중", 8, IF(L38="하", 6, "-"))) | N38: =IF(OR(O38="", O38="N/A"), "-", IF(O38="양호", 0, IF(O38="부분만족", M38/2, M38))) | O38: N/A | P38: =IF(O38="양호",'기준 DB'!C12&U38,IF(O38="취약",'기준 DB'!D12&V38,IF(OR(O38="N/A",O38="수동점검"),'기준 DB'!E12,"-")))
A39: 보안 관리 | C39: PC-12 | D39: Windows 자동 로그인 점검 | L39: 상 | M39: =IF(L39="상", 10, IF(L39="중", 8, IF(L39="하", 6, "-"))) | N39: =IF(OR(O39="", O39="N/A"), "-", IF(O39="양호", 0, IF(O39="부분만족", M39/2, M39))) | O39: N/A | P39: =IF(O39="양호",'기준 DB'!C13&U39,IF(O39="취약",'기준 DB'!D13&V39,IF(OR(O39="N/A",O39="수동점검"),'기준 DB'!E13,"-")))
C40: PC-13 | D40: 바이러스 백신 프로그램 설치 및 주기적 업데이트 | L40: 상 | M40: =IF(L40="상", 10, IF(L40="중", 8, IF(L40="하", 6, "-"))) | N40: =IF(OR(O40="", O40="N/A"), "-", IF(O40="양호", 0, IF(O40="부분만족", M40/2, M40))) | O40: N/A | P40: =IF(O40="양호",'기준 DB'!C14&U40,IF(O40="취약",'기준 DB'!D14&V40,IF(OR(O40="N/A",O40="수동점검"),'기준 DB'!E14,"-")))
C41: PC-14 | D41: 바이러스 백신 프로그램에서 제공하는 실시간 감시 기능 활성화 | L41: 상 | M41: =IF(L41="상", 10, IF(L41="중", 8, IF(L41="하", 6, "-"))) | N41: =IF(OR(O41="", O41="N/A"), "-", IF(O41="양호", 0, IF(O41="부분만족", M41/2, M41))) | O41: N/A | P41: =IF(O41="양호",'기준 DB'!C15&U41,IF(O41="취약",'기준 DB'!D15&V41,IF(OR(O41="N/A",O41="수동점검"),'기준 DB'!E15,"-")))
C42: PC-15 | D42: OS에서 제공하는 침입차단 기능 활성화 | L42: 상 | M42: =IF(L42="상", 10, IF(L42="중", 8, IF(L42="하", 6, "-"))) | N42: =IF(OR(O42="", O42="N/A"), "-", IF(O42="양호", 0, IF(O42="부분만족", M42/2, M42))) | O42: N/A | P42: =IF(O42="양호",'기준 DB'!C16&U42,IF(O42="취약",'기준 DB'!D16&V42,IF(OR(O42="N/A",O42="수동점검"),'기준 DB'!E16,"-")))
C43: PC-16 | D43: 화면보호기 대기 시간 설정 및 재시작 시 암호 보호 설정 | L43: 중 | M43: =IF(L43="상", 10, IF(L43="중", 8, IF(L43="하", 6, "-"))) | N43: =IF(OR(O43="", O43="N/A"), "-", IF(O43="양호", 0, IF(O43="부분만족", M43/2, M43))) | O43: N/A | P43: =IF(O43="양호",'기준 DB'!C17&U43,IF(O43="취약",'기준 DB'!D17&V43,IF(OR(O43="N/A",O43="수동점검"),'기준 DB'!E17,"-")))
C44: PC-17 | D44: CD, DVD, USB 메모리 등 이동식 미디어의 자동 실행 방지 | L44: 상 | M44: =IF(L44="상", 10, IF(L44="중", 8, IF(L44="하", 6, "-"))) | N44: =IF(OR(O44="", O44="N/A"), "-", IF(O44="양호", 0, IF(O44="부분만족", M44/2, M44))) | O44: N/A | P44: =IF(O44="양호",'기준 DB'!C18&U44,IF(O44="취약",'기준 DB'!D18&V44,IF(OR(O44="N/A",O44="수동점검"),'기준 DB'!E18,"-")))
C45: PC-18 | D45: 원격 지원을 금지하도록 정책이 설정 | L45: 중 | M45: =IF(L45="상", 10, IF(L45="중", 8, IF(L45="하", 6, "-"))) | N45: =IF(OR(O45="", O45="N/A"), "-", IF(O45="양호", 0, IF(O45="부분만족", M45/2, M45))) | O45: N/A | P45: =IF(O45="양호",'기준 DB'!C19&U45,IF(O45="취약",'기준 DB'!D19&V45,IF(OR(O45="N/A",O45="수동점검"),'기준 DB'!E19,"-")))
M46: =IF(L46="상", 10, IF(L46="중", 8, IF(L46="하", 6, "-"))) | N46: =IF(OR(O46="", O46="N/A"), "-", IF(O46="양호", 0, IF(O46="부분만족", M46/2, M46)))
M47: =IF(L47="상", 10, IF(L47="중", 8, IF(L47="하", 6, "-"))) | N47: =IF(OR(O47="", O47="N/A"), "-", IF(O47="양호", 0, IF(O47="부분만족", M47/2, M47)))
M48: =IF(L48="상", 10, IF(L48="중", 8, IF(L48="하", 6, "-"))) | N48: =IF(OR(O48="", O48="N/A"), "-", IF(O48="양호", 0, IF(O48="부분만족", M48/2, M48)))
M49: =IF(L49="상", 10, IF(L49="중", 8, IF(L49="하", 6, "-"))) | N49: =IF(OR(O49="", O49="N/A"), "-", IF(O49="양호", 0, IF(O49="부분만족", M49/2, M49)))
...

Sheet 기준 DB
A1: 코드 | B1: 점검 항목 | C1: 양호 | D1: 취약 | E1: N/A
A2: PC-01 | B2: 비밀번호의 주기적 변경 | C2: ■ 기준 : 최대 암호 사용 기간이 90일 이하로 설정된 경우 "양호" ■ 현황 : | D2: ■ 기준 : 최대 암호 사용 기간이 90일을 초과하거나 무제한으로 설정된 경우 "취약" ■ 현황 : | E2: ■ 기준 : 해당 항목 점검 대상 아님 ■ 현황 :
A3: PC-02 | B3: 비밀번호 관리정책 설정 | C3: ■ 기준 : 최소 암호 길이가 8자 이상이고 암호 복잡성이 설정된 경우 "양호" ■ 현황 : | D3: ■ 기준 : 최소 암호 길이가 8자 미만이거나 암호 복잡성이 설정되지 않은 경우 "취약" ■ 현황 : | E3: ■ 기준 : 해당 항목 점검 대상 아님 ■ 현황 :
A4: PC-03 | B4: 복구 콘솔에서 자동 로그온을 금지하도록 설정 | C4: ■ 기준 : 복구 콘솔 자동 로그온이 사용 안 함으로 설정된 경우 "양호" ■ 현황 : | D4: ■ 기준 : 복구 콘솔 자동 로그온이 허용된 경우 "취약" ■ 현황 : | E4: ■ 기준 : 해당 항목 점검 대상 아님 ■ 현황 :
A5: PC-04 | B5: 공유 폴더 제거 | C5: ■ 기준 : 기본 공유 및 불필요한 공유 폴더가 존재하지 않는 경우 "양호" ■ 현황 : | D5: ■ 기준 : 기본 공유 폴더(C$, ADMIN$ 등) 또는 불필요한 공유가 존재하는 경우 "취약" ■ 현황 : | E5: ■ 기준 : 해당 항목 점검 대상 아님 ■ 현황 :
A6: PC-05 | B6: 불필요한 서비스 제거 | C6: ■ 기준 : 불필요한 서비스가 사용 안 함으로 설정된 경우 "양호" ■ 현황 : | D6: ■ 기준 : 불필요한 서비스가 자동 시작으로 설정된 경우 "취약" ■ 현황 : | E6: ■ 기준 : 해당 항목 점검 대상 아님 ■ 현황 :
A7: PC-06 | B7: 비인가 상용 메신저 사용 금지 | C7: ■ 기준 : 비인가 상용 메신저가 설치되지 않은 경우 "양호" ■ 현황 : | D7: ■ 기준 : 비인가 상용 메신저가 설치되어 있는 경우 "취약" ■ 현황 : | E7: ■ 기준 : 해당 항목 점검 대상 아님 ■ 현황 :
A8: PC-07 | B8: 파일 시스템이 NTFS 포맷으로 설정 | C8: ■ 기준 : 모든 고정 드라이브의 파일 시스템이 NTFS로 설정된 경우 "양호" ■ 현황 : | D8: ■ 기준 : NTFS가 아닌 파일 시스템(FAT32 등)이 존재하는 경우 "취약" ■ 현황 : | E8: ■ 기준 : 해당 항목 점검 대상 아님 ■ 현황 :
A9: PC-08 | B9: PC 내 하나의 OS만 설치(멀티 부팅 미사용) | C9: ■ 기준 : PC 내 하나의 OS만 설치된 경우 "양호" ■ 현황 : | D9: ■ 기준 : 멀티 부팅이 설정되어 있는 경우 "취약" ■ 현황 : | E9: ■ 기준 : 해당 항목 점검 대상 아님 ■ 현황 :
A10: PC-09 | B10: 브라우저 종료 시 임시 인터넷 파일 폴더의 내용을 삭제하도록 설정 | C10: ■ 기준 : 브라우저 종료 시 임시 인터넷 파일 폴더를 비우도록 설정된 경우 "양호" ■ 현황 : | D10: ■ 기준 : 브라우저 종료 시 임시 인터넷 파일 폴더 비우기가 미사용인 경우 "취약" ■ 현황 : | E10: ■ 기준 : 해당 항목 점검 대상 아님 ■ 현황 :
A11: PC-10 | B11: 주기적 보안 패치 및 벤더 권고사항 적용 | C11: ■ 기준 : HOT FIX가 설치되어 있고 자동 업데이트가 비활성화되지 않은 경우 "양호" ■ 현황 : | D11: ■ 기준 : HOT FIX가 없거나 자동 업데이트가 비활성화된 경우 "취약" ■ 현황 : | E11: ■ 기준 : 해당 항목 점검 대상 아님 ■ 현황 :
A12: PC-11 | B12: 지원이 종료되지 않은 Windows OS Build 적용 | C12: ■ 기준 : 지원이 종료되지 않은 Windows OS Build를 사용하는 경우 "양호" ■ 현황 : | D12: ■ 기준 : 지원이 종료된 Windows OS Build를 사용하는 경우 "취약" ■ 현황 : | E12: ■ 기준 : 해당 항목 점검 대상 아님 ■ 현황 :
... A19: PC-18 | B19: 원격 지원을 금지하도록 정책이 설정 | C19: ■ 기준 : 원격 지원이 사용 안 함으로 설정된 경우 "양호" ■ 현황 : | D19: ■ 기준 : 원격 지원이 허용된 경우 "취약" ■ 현황 : | E19: ■ 기준 : 해당 항목 점검 대상 아님 ■ 현황 :
