Workbook
Name aa: #REF!
Name CASE: [1]코드!$K$35:$K$41
Name d: #REF!
Name DBMS: [1]코드!$G$35:$G$49
Name dd: #REF!
Name ddd: #REF!
Name dddd: #REF!
Name ddddd: #REF!
Name ddddddd: #REF!
Name dddfghsfthfsdh: #REF!
Name dddsadwed: #REF!
Name dfsdfsaf: #REF!
Name ds: #REF!
Name dsf: #REF!
Name dsfa: #REF!
Name dsfsf: #REF!
Name dssd: #REF!
Name d너뭔데: #REF!
Name ee: #REF!
Name EndUser: [1]코드!$D$35:$D$39
Name Evaluation: #REF!
Name fsafasdf: #REF!
Name HA상태: [2]코드표!$C$15:$C$16
Name HW: [1]코드!$I$35:$I$59
Name iii: #REF!
Name Language: [1]코드!$J$35:$J$61
Name LType: [1]코드!$M$35:$M$37
Name MW: [1]코드!$H$35:$H$49
Name NMS관제가능여부: [2]코드표!$C$52:$C$53
Name no: #REF!
Name OS: [1]코드!$F$35:$F$42
Name Platform: [1]코드!$L$35:$L$37
Name rr: #REF!
Name rrrr: #REF!
Name sasa: #REF!
Name SASDFSDF: #REF!
Name sddsd: #REF!
Name SDF: #REF!
Name sdkjfa: #REF!
Name sds: #REF!
Name sdsds: #REF!
Name sdsdsds: #REF!
Name sdsfa: #REF!
Name sf: #REF!
Name sfa: #REF!
Name sfasdfa: #REF!
Name sfddd: #REF!
Name sosos: #REF!
Name ss: #REF!
Name ssjsjks: #REF!
Name sss: #REF!
Name SW용도: [2]코드표!$B$88:$B$90
Name ui: #REF!
Name yes: #REF!
Name YN: '[3]점검표(재분류)'!#REF!
Name yy: #REF!
Name ㄱㄱ: #REF!
Name 가: #REF!
Name 가자: #REF!
Name 개발형태: [1]코드!$C$2:$C$7

Sheet 표지
B2: 구 분 | D2: 관리 | F2: 본 문서는 임의로 복사 되거나 배포될 수 없음 | P2: 대외비
B3: 문서번호
B10: [00]
B12: UNIX 서버 취약점진단 상세결과보고서
H19: 2026.00.

Sheet 개정이력
A2: ▣ 개정이력
A4: 개정번호 | B4: 개정일자 | C4: 개정내용 | D4: 작성자 | E4: 비고
A5: v0.1 | B5: 2026. 00. 00. | C5: 최초 작성 | D5: 시큐와우

Sheet 개요
A2: 1. 목적
B3: 본 보고서는 세계사이버대학의 UNIX 서버 취약점 점검 결과에 대한 보고서입니다. 따라서 본 보고서와 "보안 가이드"를 함께 참고하여 취약점이 도출된 항목에 대해 취약점을 제거 함으로써 해당 UNIX 서버의 보안 강화를 목적으로 합니다.
A5: 2. 평가 정의
B6: 2.1. 취약성 평가
C7: 2.1.1. 점검항목의 중요도 및 점수 지정
C8: 점검 결과 | E8: 평가항목의 중요도
E9: 상 | G9: 중 | I9: 하
C10: 취약 (취약점 발견) | E10: 10점 | G10: 8점 | I10: 6점
C11: 양호 (취약점 제거) | E11: 0점 | G11: 0점 | I11: 0점
C12: 부분만족 (일부취약점만 제거) | E12: 5점 | G12: 4점 | I12: 3점
C14: 2.1.2. 기술적 취약점 점수 계산
D15: • 모든 취약점이 식별 되었을 경우의 점수 합(전체점수) : A
D16: • 식별된 취약점들의 점수의 점수 합(취약점수) : B
D17: • 계산식 :
D18: • 자산의 수 : N
D19: • 자산별 점수 : S1, S2, …, SN
D20: • 계산식 :
A22: 3. 취약점 제거 방안
B23: 3.1 긴급 조치 항목 우선 제거
C24: • 긴급히 조치해야할 항목으로써 우선적으로 취약점을 제거하여 주십시오.
B26: 3.2 "보안 가이드"를 참고하여 취약점 제거
C27: • 취약한 항목의 코드와 동일한 항목을 "보안가이드"에서 해당 항목에서 찾습니다.
C28: • "보안가이드"에서 해당 항목의 <조치방안>을 참고하여 시스템 환경과 서비스에 맞도록 삭제 또는 수정 등으로 취약점을 제거하여 주십시오.
C29: • <조치방안>은 해당 자산 정보에 맞춰서 참고하시기 바랍니다.

Sheet 점검대상
A2: ▣ UNIX 점검대상
I4: DoA | J4: 7
A5: No | B5: 자산정보 | F5: 자산평가 | J5: 비고
B6: HostName | C6: O/S | D6: IP | E6: 용도 | F6: C | G6: I | H6: A | I6: 등급
A7: =HYPERLINK("[" & MID(CELL("filename"),SEARCH("[",CELL("filename"))+1, SEARCH("]",CELL("filename"))-SEARCH("[",CELL("filename"))-1) & "]'요약 통계'!" & ADDRESS(4,ROW()+5,1,TRUE),ROW()-6) -> 1 | B7: test_UNIX | C7: Ubuntu 20.04.6 LTS | D7: 192.168.1.14 | E7: 학사관리서버 | F7: 3 | G7: 3 | H7: 3 | I7: =IF(AND(SUM(F7:H7)>=8, SUM(F7:H7)<=9), "1등급", IF(AND(SUM(F7:H7)>=6, SUM(F7:H7)<=7), "2등급", IF(AND(SUM(F7:H7)>=3, SUM(F7:H7)<=5), "3등급", ""))) -> 1등급

Sheet 요약 통계
A2: ▣ UNIX 점검 요약 통계
A4: 구분 | D4: 중요도 | E4: 점수 | F4: 점검통계 | L4: =HYPERLINK("[" & MID(CELL("filename"),SEARCH("[",CELL("filename"))+1, SEARCH("]",CELL("filename"))-SEARCH("[",CELL("filename"))-1) & "]'" & INDIRECT(ADDRESS(COLUMN()-5,2,1,TRUE,"점검대상")) & "'!A1",INDIRECT(ADDRESS(COLUMN()-5,2,1,TRUE,"점검대상"))) -> test_UNIX
A5: 분류 | B5: 항목코드 | C5: 점검 항목 | F5: 전체항목 | G5: 점검항목 | H5: 양호 | I5: 취약 | J5: 부분만족 | K5: 해당없음
A6: 계정 관리 | B6: U-01 | C6: root 계정 원격 접속 제한 | D6: 상 | E6: =IF(D6="상",10,IF(D6="중",8,6)) -> 10 | F6: =COUNTA($L6:INDIRECT(ADDRESS(ROW(),MATCH("",$4:$4,-1),1,1))) -> 1 | G6: =F6-K6 -> 1 | H6: =COUNTIF($L6:INDIRECT(ADDRESS(ROW(),MATCH("",$4:$4,-1),1,1)),H$5) -> 0 | I6: =COUNTIF($L6:INDIRECT(ADDRESS(ROW(),MATCH("",$4:$4,-1),1,1)),I$5) -> 0 | J6: =COUNTIF($L6:INDIRECT(ADDRESS(ROW(),MATCH("",$4:$4,-1),1,1)),J$5) -> 0 | K6: =COUNTIF($L6:INDIRECT(ADDRESS(ROW(),MATCH("",$4:$4,-1),1,1)),"N/A") -> 0 | L6: =IFERROR(INDIRECT(ADDRESS(ROW()+22,15,1,TRUE,L$4)),"")
B7: U-02 | C7: 비밀번호 관리정책 설정 | D7: 상 | E7: =IF(D7="상",10,IF(D7="중",8,6)) -> 10 | F7: =COUNTA($L7:INDIRECT(ADDRESS(ROW(),MATCH("",$4:$4,-1),1,1))) -> 1 | G7: =F7-K7 -> 1 | H7: =COUNTIF($L7:INDIRECT(ADDRESS(ROW(),MATCH("",$4:$4,-1),1,1)),H$5) -> 0 | I7: =COUNTIF($L7:INDIRECT(ADDRESS(ROW(),MATCH("",$4:$4,-1),1,1)),I$5) -> 0 | J7: =COUNTIF($L7:INDIRECT(ADDRESS(ROW(),MATCH("",$4:$4,-1),1,1)),J$5) -> 0 | K7: =COUNTIF($L7:INDIRECT(ADDRESS(ROW(),MATCH("",$4:$4,-1),1,1)),"N/A") -> 0 | L7: =IFERROR(INDIRECT(ADDRESS(ROW()+22,15,1,TRUE,L$4)),"")
B8: U-03 | C8: 계정 잠금 임계값 설정 | D8: 상 | E8: =IF(D8="상",10,IF(D8="중",8,6)) -> 10 | F8: =COUNTA($L8:INDIRECT(ADDRESS(ROW(),MATCH("",$4:$4,-1),1,1))) -> 1 | G8: =F8-K8 -> 1 | H8: =COUNTIF($L8:INDIRECT(ADDRESS(ROW(),MATCH("",$4:$4,-1),1,1)),H$5) -> 0 | I8: =COUNTIF($L8:INDIRECT(ADDRESS(ROW(),MATCH("",$4:$4,-1),1,1)),I$5) -> 0 | J8: =COUNTIF($L8:INDIRECT(ADDRESS(ROW(),MATCH("",$4:$4,-1),1,1)),J$5) -> 0 | K8: =COUNTIF($L8:INDIRECT(ADDRESS(ROW(),MATCH("",$4:$4,-1),1,1)),"N/A") -> 0 | L8: =IFERROR(INDIRECT(ADDRESS(ROW()+22,15,1,TRUE,L$4)),"")
B9: U-04 | C9: 비밀번호 파일 보호 | D9: 상 | E9: =IF(D9="상",10,IF(D9="중",8,6)) -> 10 | F9: =COUNTA($L9:INDIRECT(ADDRESS(ROW(),MATCH("",$4:$4,-1),1,1))) -> 1 | G9: =F9-K9 -> 1 | H9: =COUNTIF($L9:INDIRECT(ADDRESS(ROW(),MATCH("",$4:$4,-1),1,1)),H$5) -> 0 | I9: =COUNTIF($L9:INDIRECT(ADDRESS(ROW(),MATCH("",$4:$4,-1),1,1)),I$5) -> 0 | J9: =COUNTIF($L9:INDIRECT(ADDRESS(ROW(),MATCH("",$4:$4,-1),1,1)),J$5) -> 0 | K9: =COUNTIF($L9:INDIRECT(ADDRESS(ROW(),MATCH("",$4:$4,-1),1,1)),"N/A") -> 0 | L9: =IFERROR(INDIRECT(ADDRESS(ROW()+22,15,1,TRUE,L$4)),"")
B10: U-05 | C10: root 이외의 UID가 '0' 금지 | D10: 상 | E10: =IF(D10="상",10,IF(D10="중",8,6)) -> 10 | F10: =COUNTA($L10:INDIRECT(ADDRESS(ROW(),MATCH("",$4:$4,-1),1,1))) -> 1 | G10: =F10-K10 -> 1 | H10: =COUNTIF($L10:INDIRECT(ADDRESS(ROW(),MATCH("",$4:$4,-1),1,1)),H$5) -> 0 | I10: =COUNTIF($L10:INDIRECT(ADDRESS(ROW(),MATCH("",$4:$4,-1),1,1)),I$5) -> 0 | J10: =COUNTIF($L10:INDIRECT(ADDRESS(ROW(),MATCH("",$4:$4,-1),1,1)),J$5) -> 0 | K10: =COUNTIF($L10:INDIRECT(ADDRESS(ROW(),MATCH("",$4:$4,-1),1,1)),"N/A") -> 0 | L10: =IFERROR(INDIRECT(ADDRESS(ROW()+22,15,1,TRUE,L$4)),"")
B11: U-06 | C11: 사용자 계정 su 기능 제한 | D11: 상 | E11: =IF(D11="상",10,IF(D11="중",8,6)) -> 10 | F11: =COUNTA($L11:INDIRECT(ADDRESS(ROW(),MATCH("",$4:$4,-1),1,1))) -> 1 | G11: =F11-K11 -> 1 | H11: =COUNTIF($L11:INDIRECT(ADDRESS(ROW(),MATCH("",$4:$4,-1),1,1)),H$5) -> 0 | I11: =COUNTIF($L11:INDIRECT(ADDRESS(ROW(),MATCH("",$4:$4,-1),1,1)),I$5) -> 0 | J11: =COUNTIF($L11:INDIRECT(ADDRESS(ROW(),MATCH("",$4:$4,-1),1,1)),J$5) -> 0 | K11: =COUNTIF($L11:INDIRECT(ADDRESS(ROW(),MATCH("",$4:$4,-1),1,1)),"N/A") -> 0 | L11: =IFERROR(INDIRECT(ADDRESS(ROW()+22,15,1,TRUE,L$4)),"")
B12: U-07 | C12: 불필요한 계정 제거 | D12: 하 | E12: =IF(D12="상",10,IF(D12="중",8,6)) -> 6 | F12: =COUNTA($L12:INDIRECT(ADDRESS(ROW(),MATCH("",$4:$4,-1),1,1))) -> 1 | G12: =F12-K12 -> 1 | H12: =COUNTIF($L12:INDIRECT(ADDRESS(ROW(),MATCH("",$4:$4,-1),1,1)),H$5) -> 0 | I12: =COUNTIF($L12:INDIRECT(ADDRESS(ROW(),MATCH("",$4:$4,-1),1,1)),I$5) -> 0 | J12: =COUNTIF($L12:INDIRECT(ADDRESS(ROW(),MATCH("",$4:$4,-1),1,1)),J$5) -> 0 | K12: =COUNTIF($L12:INDIRECT(ADDRESS(ROW(),MATCH("",$4:$4,-1),1,1)),"N/A") -> 0 | L12: =IFERROR(INDIRECT(ADDRESS(ROW()+22,15,1,TRUE,L$4)),"")
B13: U-08 | C13: 관리자 그룹에 최소한의 계정 포함 | D13: 중 | E13: =IF(D13="상",10,IF(D13="중",8,6)) -> 8 | F13: =COUNTA($L13:INDIRECT(ADDRESS(ROW(),MATCH("",$4:$4,-1),1,1))) -> 1 | G13: =F13-K13 -> 1 | H13: =COUNTIF($L13:INDIRECT(ADDRESS(ROW(),MATCH("",$4:$4,-1),1,1)),H$5) -> 0 | I13: =COUNTIF($L13:INDIRECT(ADDRESS(ROW(),MATCH("",$4:$4,-1),1,1)),I$5) -> 0 | J13: =COUNTIF($L13:INDIRECT(ADDRESS(ROW(),MATCH("",$4:$4,-1),1,1)),J$5) -> 0 | K13: =COUNTIF($L13:INDIRECT(ADDRESS(ROW(),MATCH("",$4:$4,-1),1,1)),"N/A") -> 0 | L13: =IFERROR(INDIRECT(ADDRESS(ROW()+22,15,1,TRUE,L$4)),"")
B14: U-09 | C14: 계정이 존재하지 않는 GID 금지 | D14: 하 | E14: =IF(D14="상",10,IF(D14="중",8,6)) -> 6 | F14: =COUNTA($L14:INDIRECT(ADDRESS(ROW(),MATCH("",$4:$4,-1),1,1))) -> 1 | G14: =F14-K14 -> 1 | H14: =COUNTIF($L14:INDIRECT(ADDRESS(ROW(),MATCH("",$4:$4,-1),1,1)),H$5) -> 0 | I14: =COUNTIF($L14:INDIRECT(ADDRESS(ROW(),MATCH("",$4:$4,-1),1,1)),I$5) -> 0 | J14: =COUNTIF($L14:INDIRECT(ADDRESS(ROW(),MATCH("",$4:$4,-1),1,1)),J$5) -> 0 | K14: =COUNTIF($L14:INDIRECT(ADDRESS(ROW(),MATCH("",$4:$4,-1),1,1)),"N/A") -> 0 | L14: =IFERROR(INDIRECT(ADDRESS(ROW()+22,15,1,TRUE,L$4)),"")
B15: U-10 | C15: 동일한 UID 금지 | D15: 중 | E15: =IF(D15="상",10,IF(D15="중",8,6)) -> 8 | F15: =COUNTA($L15:INDIRECT(ADDRESS(ROW(),MATCH("",$4:$4,-1),1,1))) -> 1 | G15: =F15-K15 -> 1 | H15: =COUNTIF($L15:INDIRECT(ADDRESS(ROW(),MATCH("",$4:$4,-1),1,1)),H$5) -> 0 | I15: =COUNTIF($L15:INDIRECT(ADDRESS(ROW(),MATCH("",$4:$4,-1),1,1)),I$5) -> 0 | J15: =COUNTIF($L15:INDIRECT(ADDRESS(ROW(),MATCH("",$4:$4,-1),1,1)),J$5) -> 0 | K15: =COUNTIF($L15:INDIRECT(ADDRESS(ROW(),MATCH("",$4:$4,-1),1,1)),"N/A") -> 0 | L15: =IFERROR(INDIRECT(ADDRESS(ROW()+22,15,1,TRUE,L$4)),"")
B16: U-11 | C16: 사용자 shell 점검 | D16: 하 | E16: =IF(D16="상",10,IF(D16="중",8,6)) -> 6 | F16: =COUNTA($L16:INDIRECT(ADDRESS(ROW(),MATCH("",$4:$4,-1),1,1))) -> 1 | G16: =F16-K16 -> 1 | H16: =COUNTIF($L16:INDIRECT(ADDRESS(ROW(),MATCH("",$4:$4,-1),1,1)),H$5) -> 0 | I16: =COUNTIF($L16:INDIRECT(ADDRESS(ROW(),MATCH("",$4:$4,-1),1,1)),I$5) -> 0 | J16: =COUNTIF($L16:INDIRECT(ADDRESS(ROW(),MATCH("",$4:$4,-1),1,1)),J$5) -> 0 | K16: =COUNTIF($L16:INDIRECT(ADDRESS(ROW(),MATCH("",$4:$4,-1),1,1)),"N/A") -> 0 | L16: =IFERROR(INDIRECT(ADDRESS(ROW()+22,15,1,TRUE,L$4)),"")
B17: U-12 | C17: 세션 종료 시간 설정 | D17: 하 | E17: =IF(D17="상",10,IF(D17="중",8,6)) -> 6 | F17: =COUNTA($L17:INDIRECT(ADDRESS(ROW(),MATCH("",$4:$4,-1),1,1))) -> 1 | G17: =F17-K17 -> 1 | H17: =COUNTIF($L17:INDIRECT(ADDRESS(ROW(),MATCH("",$4:$4,-1),1,1)),H$5) -> 0 | I17: =COUNTIF($L17:INDIRECT(ADDRESS(ROW(),MATCH("",$4:$4,-1),1,1)),I$5) -> 0 | J17: =COUNTIF($L17:INDIRECT(ADDRESS(ROW(),MATCH("",$4:$4,-1),1,1)),J$5) -> 0 | K17: =COUNTIF($L17:INDIRECT(ADDRESS(ROW(),MATCH("",$4:$4,-1),1,1)),"N/A") -> 0 | L17: =IFERROR(INDIRECT(ADDRESS(ROW()+22,15,1,TRUE,L$4)),"")
B18: U-13 | C18: 안전한 비밀번호 암호화 알고리즘 사용 | D18: 중 | E18: =IF(D18="상",10,IF(D18="중",8,6)) -> 8 | F18: =COUNTA($L18:INDIRECT(ADDRESS(ROW(),MATCH("",$4:$4,-1),1,1))) -> 1 | G18: =F18-K18 -> 1 | H18: =COUNTIF($L18:INDIRECT(ADDRESS(ROW(),MATCH("",$4:$4,-1),1,1)),H$5) -> 0 | I18: =COUNTIF($L18:INDIRECT(ADDRESS(ROW(),MATCH("",$4:$4,-1),1,1)),I$5) -> 0 | J18: =COUNTIF($L18:INDIRECT(ADDRESS(ROW(),MATCH("",$4:$4,-1),1,1)),J$5) -> 0 | K18: =COUNTIF($L18:INDIRECT(ADDRESS(ROW(),MATCH("",$4:$4,-1),1,1)),"N/A") -> 0 | L18: =IFERROR(INDIRECT(ADDRESS(ROW()+22,15,1,TRUE,L$4)),"")
A19: 파일 및 디렉터리 관리 | B19: U-14 | C19: root 홈, 패스 디렉터리 권한 및 패스 설정 | D19: 상 | E19: =IF(D19="상",10,IF(D19="중",8,6)) -> 10 | F19: =COUNTA($L19:INDIRECT(ADDRESS(ROW(),MATCH("",$4:$4,-1),1,1))) -> 1 | G19: =F19-K19 -> 1 | H19: =COUNTIF($L19:INDIRECT(ADDRESS(ROW(),MATCH("",$4:$4,-1),1,1)),H$5) -> 0 | I19: =COUNTIF($L19:INDIRECT(ADDRESS(ROW(),MATCH("",$4:$4,-1),1,1)),I$5) -> 0 | J19: =COUNTIF($L19:INDIRECT(ADDRESS(ROW(),MATCH("",$4:$4,-1),1,1)),J$5) -> 0 | K19: =COUNTIF($L19:INDIRECT(ADDRESS(ROW(),MATCH("",$4:$4,-1),1,1)),"N/A") -> 0 | L19: =IFERROR(INDIRECT(ADDRESS(ROW()+22,15,1,TRUE,L$4)),"")
B20: U-15 | C20: 파일 및 디렉터리 소유자 설정 | D20: 상 | E20: =IF(D20="상",10,IF(D20="중",8,6)) -> 10 | F20: =COUNTA($L20:INDIRECT(ADDRESS(ROW(),MATCH("",$4:$4,-1),1,1))) -> 1 | G20: =F20-K20 -> 1 | H20: =COUNTIF($L20:INDIRECT(ADDRESS(ROW(),MATCH("",$4:$4,-1),1,1)),H$5) -> 0 | I20: =COUNTIF($L20:INDIRECT(ADDRESS(ROW(),MATCH("",$4:$4,-1),1,1)),I$5) -> 0 | J20: =COUNTIF($L20:INDIRECT(ADDRESS(ROW(),MATCH("",$4:$4,-1),1,1)),J$5) -> 0 | K20: =COUNTIF($L20:INDIRECT(ADDRESS(ROW(),MATCH("",$4:$4,-1),1,1)),"N/A") -> 0 | L20: =IFERROR(INDIRECT(ADDRESS(ROW()+22,15,1,TRUE,L$4)),"")
B21: U-16 | C21: /etc/passwd 파일 소유자 및 권한 설정 | D21: 상 | E21: =IF(D21="상",10,IF(D21="중",8,6)) -> 10 | F21: =COUNTA($L21:INDIRECT(ADDRESS(ROW(),MATCH("",$4:$4,-1),1,1))) -> 1 | G21: =F21-K21 -> 1 | H21: =COUNTIF($L21:INDIRECT(ADDRESS(ROW(),MATCH("",$4:$4,-1),1,1)),H$5) -> 0 | I21: =COUNTIF($L21:INDIRECT(ADDRESS(ROW(),MATCH("",$4:$4,-1),1,1)),I$5) -> 0 | J21: =COUNTIF($L21:INDIRECT(ADDRESS(ROW(),MATCH("",$4:$4,-1),1,1)),J$5) -> 0 | K21: =COUNTIF($L21:INDIRECT(ADDRESS(ROW(),MATCH("",$4:$4,-1),1,1)),"N/A") -> 0 | L21: =IFERROR(INDIRECT(ADDRESS(ROW()+22,15,1,TRUE,L$4)),"")
B22: U-17 | C22: 시스템 시작 스크립트 권한 설정 | D22: 상 | E22: =IF(D22="상",10,IF(D22="중",8,6)) -> 10 | F22: =COUNTA($L22:INDIRECT(ADDRESS(ROW(),MATCH("",$4:$4,-1),1,1))) -> 1 | G22: =F22-K22 -> 1 | H22: =COUNTIF($L22:INDIRECT(ADDRESS(ROW(),MATCH("",$4:$4,-1),1,1)),H$5) -> 0 | I22: =COUNTIF($L22:INDIRECT(ADDRESS(ROW(),MATCH("",$4:$4,-1),1,1)),I$5) -> 0 | J22: =COUNTIF($L22:INDIRECT(ADDRESS(ROW(),MATCH("",$4:$4,-1),1,1)),J$5) -> 0 | K22: =COUNTIF($L22:INDIRECT(ADDRESS(ROW(),MATCH("",$4:$4,-1),1,1)),"N/A") -> 0 | L22: =IFERROR(INDIRECT(ADDRESS(ROW()+22,15,1,TRUE,L$4)),"")
B23: U-18 | C23: /etc/shadow 파일 소유자 및 권한 설정 | D23: 상 | E23: =IF(D23="상",10,IF(D23="중",8,6)) -> 10 | F23: =COUNTA($L23:INDIRECT(ADDRESS(ROW(),MATCH("",$4:$4,-1),1,1))) -> 1 | G23: =F23-K23 -> 1 | H23: =COUNTIF($L23:INDIRECT(ADDRESS(ROW(),MATCH("",$4:$4,-1),1,1)),H$5) -> 0 | I23: =COUNTIF($L23:INDIRECT(ADDRESS(ROW(),MATCH("",$4:$4,-1),1,1)),I$5) -> 0 | J23: =COUNTIF($L23:INDIRECT(ADDRESS(ROW(),MATCH("",$4:$4,-1),1,1)),J$5) -> 0 | K23: =COUNTIF($L23:INDIRECT(ADDRESS(ROW(),MATCH("",$4:$4,-1),1,1)),"N/A") -> 0 | L23: =IFERROR(INDIRECT(ADDRESS(ROW()+22,15,1,TRUE,L$4)),"")
B24: U-19 | C24: /etc/hosts 파일 소유자 및 권한 설정 | D24: 상 | E24: =IF(D24="상",10,IF(D24="중",8,6)) -> 10 | F24: =COUNTA($L24:INDIRECT(ADDRESS(ROW(),MATCH("",$4:$4,-1),1,1))) -> 1 | G24: =F24-K24 -> 1 | H24: =COUNTIF($L24:INDIRECT(ADDRESS(ROW(),MATCH("",$4:$4,-1),1,1)),H$5) -> 0 | I24: =COUNTIF($L24:INDIRECT(ADDRESS(ROW(),MATCH("",$4:$4,-1),1,1)),I$5) -> 0 | J24: =COUNTIF($L24:INDIRECT(ADDRESS(ROW(),MATCH("",$4:$4,-1),1,1)),J$5) -> 0 | K24: =COUNTIF($L24:INDIRECT(ADDRESS(ROW(),MATCH("",$4:$4,-1),1,1)),"N/A") -> 0 | L24: =IFERROR(INDIRECT(ADDRESS(ROW()+22,15,1,TRUE,L$4)),"")
B25: U-20 | C25: /etc/(x)inetd.conf 파일 소유자 및 권한 설정 | D25: 상 | E25: =IF(D25="상",10,IF(D25="중",8,6)) -> 10 | F25: =COUNTA($L25:INDIRECT(ADDRESS(ROW(),MATCH("",$4:$4,-1),1,1))) -> 1 | G25: =F25-K25 -> 1 | H25: =COUNTIF($L25:INDIRECT(ADDRESS(ROW(),MATCH("",$4:$4,-1),1,1)),H$5) -> 0 | I25: =COUNTIF($L25:INDIRECT(ADDRESS(ROW(),MATCH("",$4:$4,-1),1,1)),I$5) -> 0 | J25: =COUNTIF($L25:INDIRECT(ADDRESS(ROW(),MATCH("",$4:$4,-1),1,1)),J$5) -> 0 | K25: =COUNTIF($L25:INDIRECT(ADDRESS(ROW(),MATCH("",$4:$4,-1),1,1)),"N/A") -> 0 | L25: =IFERROR(INDIRECT(ADDRESS(ROW()+22,15,1,TRUE,L$4)),"")
B26: U-21 | C26: /etc/(r)syslog.conf 파일 소유자 및 권한 설정 | D26: 상 | E26: =IF(D26="상",10,IF(D26="중",8,6)) -> 10 | F26: =COUNTA($L26:INDIRECT(ADDRESS(ROW(),MATCH("",$4:$4,-1),1,1))) -> 1 | G26: =F26-K26 -> 1 | H26: =COUNTIF($L26:INDIRECT(ADDRESS(ROW(),MATCH("",$4:$4,-1),1,1)),H$5) -> 0 | I26: =COUNTIF($L26:INDIRECT(ADDRESS(ROW(),MATCH("",$4:$4,-1),1,1)),I$5) -> 0 | J26: =COUNTIF($L26:INDIRECT(ADDRESS(ROW(),MATCH("",$4:$4,-1),1,1)),J$5) -> 0 | K26: =COUNTIF($L26:INDIRECT(ADDRESS(ROW(),MATCH("",$4:$4,-1),1,1)),"N/A") -> 0 | L26: =IFERROR(INDIRECT(ADDRESS(ROW()+22,15,1,TRUE,L$4)),"")
B27: U-22 | C27: /etc/services 파일 소유자 및 권한 설정 | D27: 상 | E27: =IF(D27="상",10,IF(D27="중",8,6)) -> 10 | F27: =COUNTA($L27:INDIRECT(ADDRESS(ROW(),MATCH("",$4:$4,-1),1,1))) -> 1 | G27: =F27-K27 -> 1 | H27: =COUNTIF($L27:INDIRECT(ADDRESS(ROW(),MATCH("",$4:$4,-1),1,1)),H$5) -> 0 | I27: =COUNTIF($L27:INDIRECT(ADDRESS(ROW(),MATCH("",$4:$4,-1),1,1)),I$5) -> 0 | J27: =COUNTIF($L27:INDIRECT(ADDRESS(ROW(),MATCH("",$4:$4,-1),1,1)),J$5) -> 0 | K27: =COUNTIF($L27:INDIRECT(ADDRESS(ROW(),MATCH("",$4:$4,-1),1,1)),"N/A") -> 0 | L27: =IFERROR(INDIRECT(ADDRESS(ROW()+22,15,1,TRUE,L$4)),"")
B28: U-23 | C28: SUID, SGID, Sticky bit 설정 파일 점검 | D28: 상 | E28: =IF(D28="상",10,IF(D28="중",8,6)) -> 10 | F28: =COUNTA($L28:INDIRECT(ADDRESS(ROW(),MATCH("",$4:$4,-1),1,1))) -> 1 | G28: =F28-K28 -> 1 | H28: =COUNTIF($L28:INDIRECT(ADDRESS(ROW(),MATCH("",$4:$4,-1),1,1)),H$5) -> 0 | I28: =COUNTIF($L28:INDIRECT(ADDRESS(ROW(),MATCH("",$4:$4,-1),1,1)),I$5) -> 0 | J28: =COUNTIF($L28:INDIRECT(ADDRESS(ROW(),MATCH("",$4:$4,-1),1,1)),J$5) -> 0 | K28: =COUNTIF($L28:INDIRECT(ADDRESS(ROW(),MATCH("",$4:$4,-1),1,1)),"N/A") -> 0 | L28: =IFERROR(INDIRECT(ADDRESS(ROW()+22,15,1,TRUE,L$4)),"")
B29: U-24 | C29: 사용자, 시스템 환경변수 파일 소유자 및 권한 설정 | D29: 상 | E29: =IF(D29="상",10,IF(D29="중",8,6)) -> 10 | F29: =COUNTA($L29:INDIRECT(ADDRESS(ROW(),MATCH("",$4:$4,-1),1,1))) -> 1 | G29: =F29-K29 -> 1 | H29: =COUNTIF($L29:INDIRECT(ADDRESS(ROW(),MATCH("",$4:$4,-1),1,1)),H$5) -> 0 | I29: =COUNTIF($L29:INDIRECT(ADDRESS(ROW(),MATCH("",$4:$4,-1),1,1)),I$5) -> 0 | J29: =COUNTIF($L29:INDIRECT(ADDRESS(ROW(),MATCH("",$4:$4,-1),1,1)),J$5) -> 0 | K29: =COUNTIF($L29:INDIRECT(ADDRESS(ROW(),MATCH("",$4:$4,-1),1,1)),"N/A") -> 0 | L29: =IFERROR(INDIRECT(ADDRESS(ROW()+22,15,1,TRUE,L$4)),"")
B30: U-25 | C30: world writable 파일 점검 | D30: 상 | E30: =IF(D30="상",10,IF(D30="중",8,6)) -> 10 | F30: =COUNTA($L30:INDIRECT(ADDRESS(ROW(),MATCH("",$4:$4,-1),1,1))) -> 1 | G30: =F30-K30 -> 1 | H30: =COUNTIF($L30:INDIRECT(ADDRESS(ROW(),MATCH("",$4:$4,-1),1,1)),H$5) -> 0 | I30: =COUNTIF($L30:INDIRECT(ADDRESS(ROW(),MATCH("",$4:$4,-1),1,1)),I$5) -> 0 | J30: =COUNTIF($L30:INDIRECT(ADDRESS(ROW(),MATCH("",$4:$4,-1),1,1)),J$5) -> 0 | K30: =COUNTIF($L30:INDIRECT(ADDRESS(ROW(),MATCH("",$4:$4,-1),1,1)),"N/A") -> 0 | L30: =IFERROR(INDIRECT(ADDRESS(ROW()+22,15,1,TRUE,L$4)),"")
B31: U-26 | C31: /dev에 존재하지 않는 device 파일 점검 | D31: 상 | E31: =IF(D31="상",10,IF(D31="중",8,6)) -> 10 | F31: =COUNTA($L31:INDIRECT(ADDRESS(ROW(),MATCH("",$4:$4,-1),1,1))) -> 1 | G31: =F31-K31 -> 1 | H31: =COUNTIF($L31:INDIRECT(ADDRESS(ROW(),MATCH("",$4:$4,-1),1,1)),H$5) -> 0 | I31: =COUNTIF($L31:INDIRECT(ADDRESS(ROW(),MATCH("",$4:$4,-1),1,1)),I$5) -> 0 | J31: =COUNTIF($L31:INDIRECT(ADDRESS(ROW(),MATCH("",$4:$4,-1),1,1)),J$5) -> 0 | K31: =COUNTIF($L31:INDIRECT(ADDRESS(ROW(),MATCH("",$4:$4,-1),1,1)),"N/A") -> 0 | L31: =IFERROR(INDIRECT(ADDRESS(ROW()+22,15,1,TRUE,L$4)),"")
... B38: U-33 | C38: 숨겨진 파일 및 디렉터리 검색 및 제거 | D38: 하 | E38: =IF(D38="상",10,IF(D38="중",8,6)) -> 6 | F38: =COUNTA($L38:INDIRECT(ADDRESS(ROW(),MATCH("",$4:$4,-1),1,1))) -> 1 | G38: =F38-K38 -> 1 | H38: =COUNTIF($L38:INDIRECT(ADDRESS(ROW(),MATCH("",$4:$4,-1),1,1)),H$5) -> 0 | I38: =COUNTIF($L38:INDIRECT(ADDRESS(ROW(),MATCH("",$4:$4,-1),1,1)),I$5) -> 0 | J38: =COUNTIF($L38:INDIRECT(ADDRESS(ROW(),MATCH("",$4:$4,-1),1,1)),J$5) -> 0 | K38: =COUNTIF($L38:INDIRECT(ADDRESS(ROW(),MATCH("",$4:$4,-1),1,1)),"N/A") -> 0 | L38: =IFERROR(INDIRECT(ADDRESS(ROW()+22,15,1,TRUE,L$4)),"")
A39: 서비스 관리 | B39: U-34 | C39: Finger 서비스 비활성화 | D39: 상 | E39: =IF(D39="상",10,IF(D39="중",8,6)) -> 10 | F39: =COUNTA($L39:INDIRECT(ADDRESS(ROW(),MATCH("",$4:$4,-1),1,1))) -> 1 | G39: =F39-K39 -> 1 | H39: =COUNTIF($L39:INDIRECT(ADDRESS(ROW(),MATCH("",$4:$4,-1),1,1)),H$5) -> 0 | I39: =COUNTIF($L39:INDIRECT(ADDRESS(ROW(),MATCH("",$4:$4,-1),1,1)),I$5) -> 0 | J39: =COUNTIF($L39:INDIRECT(ADDRESS(ROW(),MATCH("",$4:$4,-1),1,1)),J$5) -> 0 | K39: =COUNTIF($L39:INDIRECT(ADDRESS(ROW(),MATCH("",$4:$4,-1),1,1)),"N/A") -> 0 | L39: =IFERROR(INDIRECT(ADDRESS(ROW()+22,15,1,TRUE,L$4)),"")
B40: U-35 | C40: 공유 서비스에 대한 익명 접근 제한 설정 | D40: 상 | E40: =IF(D40="상",10,IF(D40="중",8,6)) -> 10 | F40: =COUNTA($L40:INDIRECT(ADDRESS(ROW(),MATCH("",$4:$4,-1),1,1))) -> 1 | G40: =F40-K40 -> 1 | H40: =COUNTIF($L40:INDIRECT(ADDRESS(ROW(),MATCH("",$4:$4,-1),1,1)),H$5) -> 0 | I40: =COUNTIF($L40:INDIRECT(ADDRESS(ROW(),MATCH("",$4:$4,-1),1,1)),I$5) -> 0 | J40: =COUNTIF($L40:INDIRECT(ADDRESS(ROW(),MATCH("",$4:$4,-1),1,1)),J$5) -> 0 | K40: =COUNTIF($L40:INDIRECT(ADDRESS(ROW(),MATCH("",$4:$4,-1),1,1)),"N/A") -> 0 | L40: =IFERROR(INDIRECT(ADDRESS(ROW()+22,15,1,TRUE,L$4)),"")
B41: U-36 | C41: r 계열 서비스 비활성화 | D41: 상 | E41: =IF(D41="상",10,IF(D41="중",8,6)) -> 10 | F41: =COUNTA($L41:INDIRECT(ADDRESS(ROW(),MATCH("",$4:$4,-1),1,1))) -> 1 | G41: =F41-K41 -> 1 | H41: =COUNTIF($L41:INDIRECT(ADDRESS(ROW(),MATCH("",$4:$4,-1),1,1)),H$5) -> 0 | I41: =COUNTIF($L41:INDIRECT(ADDRESS(ROW(),MATCH("",$4:$4,-1),1,1)),I$5) -> 0 | J41: =COUNTIF($L41:INDIRECT(ADDRESS(ROW(),MATCH("",$4:$4,-1),1,1)),J$5) -> 0 | K41: =COUNTIF($L41:INDIRECT(ADDRESS(ROW(),MATCH("",$4:$4,-1),1,1)),"N/A") -> 0 | L41: =IFERROR(INDIRECT(ADDRESS(ROW()+22,15,1,TRUE,L$4)),"")
B42: U-37 | C42: crontab 설정파일 권한 설정 미흡 | D42: 상 | E42: =IF(D42="상",10,IF(D42="중",8,6)) -> 10 | F42: =COUNTA($L42:INDIRECT(ADDRESS(ROW(),MATCH("",$4:$4,-1),1,1))) -> 1 | G42: =F42-K42 -> 1 | H42: =COUNTIF($L42:INDIRECT(ADDRESS(ROW(),MATCH("",$4:$4,-1),1,1)),H$5) -> 0 | I42: =COUNTIF($L42:INDIRECT(ADDRESS(ROW(),MATCH("",$4:$4,-1),1,1)),I$5) -> 0 | J42: =COUNTIF($L42:INDIRECT(ADDRESS(ROW(),MATCH("",$4:$4,-1),1,1)),J$5) -> 0 | K42: =COUNTIF($L42:INDIRECT(ADDRESS(ROW(),MATCH("",$4:$4,-1),1,1)),"N/A") -> 0 | L42: =IFERROR(INDIRECT(ADDRESS(ROW()+22,15,1,TRUE,L$4)),"")
B43: U-38 | C43: DoS 공격에 취약한 서비스 비활성화 | D43: 상 | E43: =IF(D43="상",10,IF(D43="중",8,6)) -> 10 | F43: =COUNTA($L43:INDIRECT(ADDRESS(ROW(),MATCH("",$4:$4,-1),1,1))) -> 1 | G43: =F43-K43 -> 1 | H43: =COUNTIF($L43:INDIRECT(ADDRESS(ROW(),MATCH("",$4:$4,-1),1,1)),H$5) -> 0 | I43: =COUNTIF($L43:INDIRECT(ADDRESS(ROW(),MATCH("",$4:$4,-1),1,1)),I$5) -> 0 | J43: =COUNTIF($L43:INDIRECT(ADDRESS(ROW(),MATCH("",$4:$4,-1),1,1)),J$5) -> 0 | K43: =COUNTIF($L43:INDIRECT(ADDRESS(ROW(),MATCH("",$4:$4,-1),1,1)),"N/A") -> 0 | L43: =IFERROR(INDIRECT(ADDRESS(ROW()+22,15,1,TRUE,L$4)),"")
B44: U-39 | C44: 불필요한 NFS 서비스 비활성화 | D44: 상 | E44: =IF(D44="상",10,IF(D44="중",8,6)) -> 10 | F44: =COUNTA($L44:INDIRECT(ADDRESS(ROW(),MATCH("",$4:$4,-1),1,1))) -> 1 | G44: =F44-K44 -> 1 | H44: =COUNTIF($L44:INDIRECT(ADDRESS(ROW(),MATCH("",$4:$4,-1),1,1)),H$5) -> 0 | I44: =COUNTIF($L44:INDIRECT(ADDRESS(ROW(),MATCH("",$4:$4,-1),1,1)),I$5) -> 0 | J44: =COUNTIF($L44:INDIRECT(ADDRESS(ROW(),MATCH("",$4:$4,-1),1,1)),J$5) -> 0 | K44: =COUNTIF($L44:INDIRECT(ADDRESS(ROW(),MATCH("",$4:$4,-1),1,1)),"N/A") -> 0 | L44: =IFERROR(INDIRECT(ADDRESS(ROW()+22,15,1,TRUE,L$4)),"")
B45: U-40 | C45: NFS 접근통제 | D45: 상 | E45: =IF(D45="상",10,IF(D45="중",8,6)) -> 10 | F45: =COUNTA($L45:INDIRECT(ADDRESS(ROW(),MATCH("",$4:$4,-1),1,1))) -> 1 | G45: =F45-K45 -> 1 | H45: =COUNTIF($L45:INDIRECT(ADDRESS(ROW(),MATCH("",$4:$4,-1),1,1)),H$5) -> 0 | I45: =COUNTIF($L45:INDIRECT(ADDRESS(ROW(),MATCH("",$4:$4,-1),1,1)),I$5) -> 0 | J45: =COUNTIF($L45:INDIRECT(ADDRESS(ROW(),MATCH("",$4:$4,-1),1,1)),J$5) -> 0 | K45: =COUNTIF($L45:INDIRECT(ADDRESS(ROW(),MATCH("",$4:$4,-1),1,1)),"N/A") -> 0 | L45: =IFERROR(INDIRECT(ADDRESS(ROW()+22,15,1,TRUE,L$4)),"")
B46: U-41 | C46: 불필요한 automountd 제거 | D46: 상 | E46: =IF(D46="상",10,IF(D46="중",8,6)) -> 10 | F46: =COUNTA($L46:INDIRECT(ADDRESS(ROW(),MATCH("",$4:$4,-1),1,1))) -> 1 | G46: =F46-K46 -> 1 | H46: =COUNTIF($L46:INDIRECT(ADDRESS(ROW(),MATCH("",$4:$4,-1),1,1)),H$5) -> 0 | I46: =COUNTIF($L46:INDIRECT(ADDRESS(ROW(),MATCH("",$4:$4,-1),1,1)),I$5) -> 0 | J46: =COUNTIF($L46:INDIRECT(ADDRESS(ROW(),MATCH("",$4:$4,-1),1,1)),J$5) -> 0 | K46: =COUNTIF($L46:INDIRECT(ADDRESS(ROW(),MATCH("",$4:$4,-1),1,1)),"N/A") -> 0 | L46: =IFERROR(INDIRECT(ADDRESS(ROW()+22,15,1,TRUE,L$4)),"")
B47: U-42 | C47: 불필요한 RPC 서비스 확인 | D47: 상 | E47: =IF(D47="상",10,IF(D47="중",8,6)) -> 10 | F47: =COUNTA($L47:INDIRECT(ADDRESS(ROW(),MATCH("",$4:$4,-1),1,1))) -> 1 | G47: =F47-K47 -> 1 | H47: =COUNTIF($L47:INDIRECT(ADDRESS(ROW(),MATCH("",$4:$4,-1),1,1)),H$5) -> 0 | I47: =COUNTIF($L47:INDIRECT(ADDRESS(ROW(),MATCH("",$4:$4,-1),1,1)),I$5) -> 0 | J47: =COUNTIF($L47:INDIRECT(ADDRESS(ROW(),MATCH("",$4:$4,-1),1,1)),J$5) -> 0 | K47: =COUNTIF($L47:INDIRECT(ADDRESS(ROW(),MATCH("",$4:$4,-1),1,1)),"N/A") -> 0 | L47: =IFERROR(INDIRECT(ADDRESS(ROW()+22,15,1,TRUE,L$4)),"")
B48: U-43 | C48: NIS, NIS+ 점검 | D48: 상 | E48: =IF(D48="상",10,IF(D48="중",8,6)) -> 10 | F48: =COUNTA($L48:INDIRECT(ADDRESS(ROW(),MATCH("",$4:$4,-1),1,1))) -> 1 | G48: =F48-K48 -> 1 | H48: =COUNTIF($L48:INDIRECT(ADDRESS(ROW(),MATCH("",$4:$4,-1),1,1)),H$5) -> 0 | I48: =COUNTIF($L48:INDIRECT(ADDRESS(ROW(),MATCH("",$4:$4,-1),1,1)),I$5) -> 0 | J48: =COUNTIF($L48:INDIRECT(ADDRESS(ROW(),MATCH("",$4:$4,-1),1,1)),J$5) -> 0 | K48: =COUNTIF($L48:INDIRECT(ADDRESS(ROW(),MATCH("",$4:$4,-1),1,1)),"N/A") -> 0 | L48: =IFERROR(INDIRECT(ADDRESS(ROW()+22,15,1,TRUE,L$4)),"")
...

Sheet 보안수준 통계
A2: ▣ 점검 영역별 보안수준
A4: 구분 | C4: 점검 결과 | I4: 점검 점수
C5: 전체항목 | D5: 점검항목 | E5: 양호 | F5: 취약 | G5: 부분만족 | H5: 해당없음 | I5: 전체점수 | J5: 취약점수 | K5: 보안수준
A6: 계정 관리 | C6: =SUM('sample:기준 DB'!D18) -> 13 | D6: =SUM('sample:기준 DB'!E18) -> 12 | E6: =SUM('sample:기준 DB'!F18) -> 11 | F6: =SUM('sample:기준 DB'!G18) -> 1 | G6: =SUM('sample:기준 DB'!H18) -> 0 | H6: =SUM('sample:기준 DB'!I18) -> 1 | I6: =SUM('sample:기준 DB'!J18) -> 108 | J6: =SUM('sample:기준 DB'!K18) -> 10 | K6: =IF(I6=0,"N/A",((I6-J6)/I6)*1) -> 0.90740741
A7: 파일 및 디렉터리 관리 | C7: =SUM('sample:기준 DB'!D19) -> 20 | D7: =SUM('sample:기준 DB'!E19) -> 19 | E7: =SUM('sample:기준 DB'!F19) -> 18 | F7: =SUM('sample:기준 DB'!G19) -> 1 | G7: =SUM('sample:기준 DB'!H19) -> 0 | H7: =SUM('sample:기준 DB'!I19) -> 1 | I7: =SUM('sample:기준 DB'!J19) -> 186 | J7: =SUM('sample:기준 DB'!K19) -> 10 | K7: =IF(I7=0,"N/A",((I7-J7)/I7)*1) -> 0.94623656
A8: 서비스 관리 | C8: =SUM('sample:기준 DB'!D20) -> 30 | D8: =SUM('sample:기준 DB'!E20) -> 29 | E8: =SUM('sample:기준 DB'!F20) -> 28 | F8: =SUM('sample:기준 DB'!G20) -> 1 | G8: =SUM('sample:기준 DB'!H20) -> 0 | H8: =SUM('sample:기준 DB'!I20) -> 1 | I8: =SUM('sample:기준 DB'!J20) -> 270 | J8: =SUM('sample:기준 DB'!K20) -> 10 | K8: =IF(I8=0,"N/A",((I8-J8)/I8)*1) -> 0.96296296
A9: 패치 관리 | C9: =SUM('sample:기준 DB'!D21) -> 1 | D9: =SUM('sample:기준 DB'!E21) -> 1 | E9: =SUM('sample:기준 DB'!F21) -> 1 | F9: =SUM('sample:기준 DB'!G21) -> 0 | G9: =SUM('sample:기준 DB'!H21) -> 0 | H9: =SUM('sample:기준 DB'!I21) -> 0 | I9: =SUM('sample:기준 DB'!J21) -> 10 | J9: =SUM('sample:기준 DB'!K21) -> 0 | K9: =IF(I9=0,"N/A",((I9-J9)/I9)*1) -> 1
A10: 로그 관리 | C10: =SUM('sample:기준 DB'!D22) -> 3 | D10: =SUM('sample:기준 DB'!E22) -> 2 | E10: =SUM('sample:기준 DB'!F22) -> 1 | F10: =SUM('sample:기준 DB'!G22) -> 1 | G10: =SUM('sample:기준 DB'!H22) -> 0 | H10: =SUM('sample:기준 DB'!I22) -> 1 | I10: =SUM('sample:기준 DB'!J22) -> 24 | J10: =SUM('sample:기준 DB'!K22) -> 8 | K10: =IF(I10=0,"N/A",((I10-J10)/I10)*1) -> 0.66666667
A11: 계 | C11: =SUM(C6:C10) -> 67 | D11: =SUM(D6:D10) -> 63 | E11: =SUM(E6:E10) -> 59 | F11: =SUM(F6:F10) -> 4 | G11: =SUM(G6:G10) -> 0 | H11: =SUM(H6:H10) -> 4 | I11: =SUM(I6:I10) -> 598 | J11: =SUM(J6:J10) -> 38 | K11: =K37 -> #DIV/0!
A13: ▣ 점검 영역별 보안수준 그래프
A32: ▣ 장비별 보안수준
A34: Host 명 | C34: 점검 결과 | I34: 점검 점수
C35: 전체항목 | D35: 점검항목 | E35: 양호 | F35: 취약 | G35: 부분만족 | H35: 해당없음 | I35: 전체점수 | J35: 취약점수 | K35: 보안수준
A36: UNIX | B36: =INDIRECT(ADDRESS(ROW()-29,2,1,TRUE,"점검대상")) -> test_UNIX | C36: =IFERROR(INDIRECT(ADDRESS(23,COLUMN()+1,1,TRUE,$B36)),0) -> 0 | D36: =IFERROR(INDIRECT(ADDRESS(23,COLUMN()+1,1,TRUE,$B36)),0) -> 0 | E36: =IFERROR(INDIRECT(ADDRESS(23,COLUMN()+1,1,TRUE,$B36)),0) -> 0 | F36: =IFERROR(INDIRECT(ADDRESS(23,COLUMN()+1,1,TRUE,$B36)),0) -> 0 | G36: =IFERROR(INDIRECT(ADDRESS(23,COLUMN()+1,1,TRUE,$B36)),0) -> 0 | H36: =IFERROR(INDIRECT(ADDRESS(23,COLUMN()+1,1,TRUE,$B36)),0) -> 0 | I36: =IFERROR(INDIRECT(ADDRESS(23,COLUMN()+1,1,TRUE,$B36)),0) -> 0 | J36: =IFERROR(INDIRECT(ADDRESS(23,COLUMN()+1,1,TRUE,$B36)),0) -> 0 | K36: =IF(I36=0,"N/A",((I36-J36)/I36)*1) -> N/A
A37: 계 | C37: =SUM(C36:C36) -> 0 | D37: =SUM(D36:D36) -> 0 | E37: =SUM(E36:E36) -> 0 | F37: =SUM(F36:F36) -> 0 | G37: =SUM(G36:G36) -> 0 | H37: =SUM(H36:H36) -> 0 | I37: =SUM(I36:I36) -> 0 | J37: =SUM(J36:J36) -> 0 | K37: =SUM(K36:K36)/(COUNTA(K36:K36)-COUNTIF(K36:K36,"N/A")) -> #DIV/0!

Sheet sample
A2: ▣ 장비별 점검 상세 결과 | E2: =HYPERLINK("[" & MID(CELL("filename"),SEARCH("[",CELL("filename"))+1, SEARCH("]",CELL("filename"))-SEARCH("[",CELL("filename"))-1) & "]'" & "점검대상" & "'!A1","목 차") -> 목 차
A4: ▣ 시스템 현황
A6: Host Name | C6: =MID(CELL("filename",$A$1),FIND("]",CELL("filename",$A$1))+1,100) -> sample | G6: O/S | I6: =IFERROR(VLOOKUP($C$6,점검대상!$B:$I,2,FALSE),"-") -> - | P6: ▣ 장비별 보안수준 그래프
A7: IP Address | C7: =IFERROR(VLOOKUP($C$6,점검대상!$B:$I,3,FALSE),"-") -> - | G7: 용도 | I7: =IFERROR(VLOOKUP($C$6,점검대상!$B:$I,4,FALSE),"-") -> -
A9: ▣ 자산평가
A11: 자산가치 | C11: C | D11: I | E11: A | F11: 중요도 | H11: 등급 | J11: DoA
C12: =IFERROR(VLOOKUP($C$6,점검대상!$B:$I,COLUMN()+2,FALSE),"-") -> - | D12: =IFERROR(VLOOKUP($C$6,점검대상!$B:$I,COLUMN()+2,FALSE),"-") -> - | E12: =IFERROR(VLOOKUP($C$6,점검대상!$B:$I,COLUMN()+2,FALSE),"-") -> - | F12: =SUM(C12:E12) -> 0 | H12: =IF(F12>=7,"상",IF(F12>=5,"중","하")) -> 하 | J12: =점검대상!$J$4 -> 7
A14: ▣ 영역별 점검 결과
A16: 분류 | D16: 항목 통계 | J16: 점검 점수
D17: 전체 | E17: 점검 | F17: 양호 | G17: 취약 | H17: 부분만족 | I17: 해당없음 | J17: 전체점수 | K17: 취약점수 | L17: 보안수준
A18: 계정 관리 | D18: 13 | E18: =$D18-I18 -> 12 | F18: =COUNTIF(O28:O40,"양호") -> 11 | G18: =D18-I18-H18-F18 -> 1 | H18: 0 | I18: =COUNTIF(O28:O40,"N/A") -> 1 | J18: =SUM(M28:M40) -> 108 | K18: =SUM(N28:N40) -> 10 | L18: =IF(J18=0,"N/A",((J18-K18)/J18)*1) -> 0.90740741
A19: 파일 및 디렉터리 관리 | D19: 20 | E19: =$D19-I19 -> 19 | F19: =COUNTIF(O41:O60,"양호") -> 18 | G19: =D19-I19-H19-F19 -> 1 | H19: 0 | I19: =COUNTIF(O41:O60,"N/A") -> 1 | J19: =SUM(M41:M60) -> 186 | K19: =SUM(N41:N60) -> 10 | L19: =IF(J19=0,"N/A",((J19-K19)/J19)*1) -> 0.94623656
A20: 서비스 관리 | D20: 30 | E20: =$D20-I20 -> 29 | F20: =COUNTIF(O61:O90,"양호") -> 28 | G20: =D20-I20-H20-F20 -> 1 | H20: 0 | I20: =COUNTIF(O61:O90,"N/A") -> 1 | J20: =SUM(M61:M90) -> 270 | K20: =SUM(N61:N90) -> 10 | L20: =IF(J20=0,"N/A",((J20-K20)/J20)*1) -> 0.96296296
A21: 패치 관리 | D21: 1 | E21: =$D21-I21 -> 1 | F21: =COUNTIF(O91,"양호") -> 1 | G21: =D21-I21-H21-F21 -> 0 | H21: 0 | I21: =COUNTIF(O91,"N/A") -> 0 | J21: =SUM(M91) -> 10 | K21: =SUM(N91) -> 0 | L21: =IF(J21=0,"N/A",((J21-K21)/J21)*1) -> 1
A22: 로그 관리 | D22: 3 | E22: =$D22-I22 -> 2 | F22: =COUNTIF(O92:O94,"양호") -> 1 | G22: =D22-I22-H22-F22 -> 1 | H22: 0 | I22: =COUNTIF(O92:O94,"N/A") -> 1 | J22: =SUM(M92:M94) -> 24 | K22: =SUM(N92:N94) -> 8 | L22: =IF(J22=0,"N/A",((J22-K22)/J22)*1) -> 0.66666667
A23: 전체 보안 수준 | D23: 67 | E23: =SUM(E18:E22) -> 63 | F23: =SUM(F18:F22) -> 59 | G23: =SUM(G18:G22) -> 4 | H23: =SUM(H18:H22) -> 0 | I23: =SUM(I18:I22) -> 4 | J23: =SUM(J18:J22) -> 598 | K23: =SUM(K18:K22) -> 38 | L23: =IF(J23=0,"N/A",((J23-K23)/J23)*1) -> 0.93645485
A25: ▣ 상세 점검 현황 | Q25: (취약점제거: '양호', 취약점발견: '취약', 일부 취약점만 제거: '부분만족', 해당사항없음: 'N/A')
A27: 구분 | C27: 점검 항목 | L27: 중요도 | M27: 중요도 값 | N27: 점검 결과 값 | O27: 점검결과 | P27: 점검현황 | Q27: 운영현황 | U27: 점검 현황 사항 입력 란
A28: 계정 관리 | C28: U-01 | D28: root 계정 원격 접속 제한 | L28: 상 | M28: =IF(L28="상", 10, IF(L28="중", 8, IF(L28="하", 6, "-"))) -> 10 | N28: =IF(OR(O28="", O28="N/A"), "-", IF(O28="양호", 0, IF(O28="부분만족", M28/2, M28))) -> 10 | O28: 취약 | P28: =IF(O28="양호",'기준 DB'!C2&U28,IF(O28="취약",'기준 DB'!D2&U28,IF(O28="N/A",'기준 DB'!E2&U28,"-"))) -> ■ 기준 : root 직접 접속을 허용하고 원격 서비스를 사용하는 경우 "취약" ■ 현황 : TELNET 서비스가 비실행중이고, SSH의 root 원격 접속을 제한하지 않으므로 취약함 | U28: TELNET 서비스가 비실행중이고, SSH의 root 원격 접속을 제한하지 않으므로 취약함
C29: U-02 | D29: 비밀번호 관리정책 설정 | L29: 상 | M29: =IF(L29="상", 10, IF(L29="중", 8, IF(L29="하", 6, "-"))) -> 10 | O29: N/A | P29: =IF(O29="양호",'기준 DB'!C3&U29,IF(O29="취약",'기준 DB'!D3&U29,IF(O29="N/A",'기준 DB'!E3&U29,"-"))) -> ■ 기준 : 비밀번호 관리 정책이 설정된 경우 "양호" 비밀번호 관리 정책이 설정되지 않은 경우 "취약" ■ 현황 : 패스워드 복잡성 설정이 되어 있지 않으므로 취약함 | U29: 패스워드 복잡성 설정이 되어 있지 않으므로 취약함
C30: U-03 | D30: 계정 잠금 임계값 설정 | L30: 상 | M30: =IF(L30="상", 10, IF(L30="중", 8, IF(L30="하", 6, "-"))) -> 10 | N30: =IF(OR(O30="", O30="N/A"), "-", IF(O30="양호", 0, IF(O30="부분만족", M30/2, M30))) -> 0 | O30: 양호 | P30: =IF(O30="양호",'기준 DB'!C4&U30,IF(O30="취약",'기준 DB'!D4&U30,IF(O30="N/A",'기준 DB'!E4&U30,"-"))) -> ■ 기준 : 계정 잠금 임계값이 10회 이하의 값으로 설정되어 있는 경우 "양호" ■ 현황 : 계정 잠금 임계값 설정 파일이 없음으로 취약함 | U30: 계정 잠금 임계값 설정 파일이 없음으로 취약함
C31: U-04 | D31: 비밀번호 파일 보호 | L31: 상 | M31: =IF(L31="상", 10, IF(L31="중", 8, IF(L31="하", 6, "-"))) -> 10 | N31: =IF(OR(O31="", O31="N/A"), "-", IF(O31="양호", 0, IF(O31="부분만족", M31/2, M31))) -> 0 | O31: 양호 | P31: =IF(O31="양호",'기준 DB'!C5&U31,IF(O31="취약",'기준 DB'!D5&U31,IF(O31="N/A",'기준 DB'!E5&U31,"-"))) -> ■ 기준 : 쉐도우 비밀번호를 사용하거나, 비밀번호를 암호화하여 저장하는 경우 "양호" ■ 현황 : shadow 파일을 사용하고 있으므로 양호함 | U31: shadow 파일을 사용하고 있으므로 양호함
C32: U-05 | D32: root 이외의 UID가 '0' 금지 | L32: 상 | M32: =IF(L32="상", 10, IF(L32="중", 8, IF(L32="하", 6, "-"))) -> 10 | N32: =IF(OR(O32="", O32="N/A"), "-", IF(O32="양호", 0, IF(O32="부분만족", M32/2, M32))) -> 0 | O32: 양호 | P32: =IF(O32="양호",'기준 DB'!C6&U32,IF(O32="취약",'기준 DB'!D6&U32,IF(O32="N/A",'기준 DB'!E6&U32,"-"))) -> ■ 기준 : root 계정과 동일한 UID를 갖는 계정이 존재하지 않는 경우 "양호" ■ 현황 : root 이외의 UID가 '0'인 계정이 존재하지 않으므로 양호함 | U32: root 이외의 UID가 '0'인 계정이 존재하지 않으므로 양호함
C33: U-06 | D33: 사용자 계정 su 기능 제한 | L33: 상 | M33: =IF(L33="상", 10, IF(L33="중", 8, IF(L33="하", 6, "-"))) -> 10 | N33: =IF(OR(O33="", O33="N/A"), "-", IF(O33="양호", 0, IF(O33="부분만족", M33/2, M33))) -> 0 | O33: 양호 | P33: =IF(O33="양호",'기준 DB'!C7&U33,IF(O33="취약",'기준 DB'!D7&U33,IF(O33="N/A",'기준 DB'!E7&U33,"-"))) -> ■ 기준 : su 명령어를 특정 그룹에 속한 사용자만 사용하도록 제한된 경우 "양호" ※ 일반 사용자 계정 없이 root 계정만 사용하는 경우 su 명령어 사용 제한 불필요 ■ 현황 : /bin/su 파일의 접근권한이 과도하게 설정되어 있으므로 취약함 | U33: /bin/su 파일의 접근권한이 과도하게 설정되어 있으므로 취약함
C34: U-07 | D34: 불필요한 계정 제거 | L34: 하 | M34: =IF(L34="상", 10, IF(L34="중", 8, IF(L34="하", 6, "-"))) -> 6 | N34: =IF(OR(O34="", O34="N/A"), "-", IF(O34="양호", 0, IF(O34="부분만족", M34/2, M34))) -> 0 | O34: 양호 | P34: =IF(O34="양호",'기준 DB'!C8&U34,IF(O34="취약",'기준 DB'!D8&U34,IF(O34="N/A",'기준 DB'!E8&U34,"-"))) -> ■ 기준 : 불필요한 계정이 존재하지 않는 경우 "양호" ■ 현황 : 패스워드 최소길이가 설정되어 있지 않으므로 취약함 | U34: 패스워드 최소길이가 설정되어 있지 않으므로 취약함
C35: U-08 | D35: 관리자 그룹에 최소한의 계정 포함 | L35: 중 | M35: =IF(L35="상", 10, IF(L35="중", 8, IF(L35="하", 6, "-"))) -> 8 | N35: =IF(OR(O35="", O35="N/A"), "-", IF(O35="양호", 0, IF(O35="부분만족", M35/2, M35))) -> 0 | O35: 양호 | P35: =IF(O35="양호",'기준 DB'!C9&U35,IF(O35="취약",'기준 DB'!D9&U35,IF(O35="N/A",'기준 DB'!E9&U35,"-"))) -> ■ 기준 : 관리자 그룹에 불필요한 계정이 등록되어 있지 않은 경우 "양호" ■ 현황 : 패스워드 최대 사용기간이 90일(12주) 이하로 설정되어 있지 않으므로 취약함 | U35: 패스워드 최대 사용기간이 90일(12주) 이하로 설정되어 있지 않으므로 취약함
C36: U-09 | D36: 계정이 존재하지 않는 GID 금지 | L36: 하 | M36: =IF(L36="상", 10, IF(L36="중", 8, IF(L36="하", 6, "-"))) -> 6 | N36: =IF(OR(O36="", O36="N/A"), "-", IF(O36="양호", 0, IF(O36="부분만족", M36/2, M36))) -> 0 | O36: 양호 | P36: =IF(O36="양호",'기준 DB'!C10&U36,IF(O36="취약",'기준 DB'!D10&U36,IF(O36="N/A",'기준 DB'!E10&U36,"-"))) -> ■ 기준 : 시스템 관리나 운용에 불필요한 그룹이 제거된 경우 "양호" ■ 현황 : 패스워드 최소 사용기간이 1일(1주)로 설정되어 있지 않으므로 취약함 | U36: 패스워드 최소 사용기간이 1일(1주)로 설정되어 있지 않으므로 취약함
C37: U-10 | D37: 동일한 UID 금지 | L37: 중 | M37: =IF(L37="상", 10, IF(L37="중", 8, IF(L37="하", 6, "-"))) -> 8 | N37: =IF(OR(O37="", O37="N/A"), "-", IF(O37="양호", 0, IF(O37="부분만족", M37/2, M37))) -> 0 | O37: 양호 | P37: =IF(O37="양호",'기준 DB'!C11&U37,IF(O37="취약",'기준 DB'!D11&U37,IF(O37="N/A",'기준 DB'!E11&U37,"-"))) -> ■ 기준 : 동일한 UID로 설정된 사용자 계정이 존재하지 않는 경우 "양호" ■ 현황 : 불필요한 계정이 없어 양호함 | U37: 불필요한 계정이 없어 양호함
C38: U-11 | D38: 사용자 shell 점검 | L38: 하 | M38: =IF(L38="상", 10, IF(L38="중", 8, IF(L38="하", 6, "-"))) -> 6 | N38: =IF(OR(O38="", O38="N/A"), "-", IF(O38="양호", 0, IF(O38="부분만족", M38/2, M38))) -> 0 | O38: 양호 | P38: =IF(O38="양호",'기준 DB'!C12&U38,IF(O38="취약",'기준 DB'!D12&U38,IF(O38="N/A",'기준 DB'!E12&U38,"-"))) -> ■ 기준 : 로그인이 필요하지 않은 계정에 /bin/false(nologin) 쉘이 부여되어 있는 경우 "양호" ■ 현황 : "root:x:0:" 으로 root 그룹에 최소한의 계정만 설정되어 있음으로 양호 | U38: "root:x:0:" 으로 root 그룹에 최소한의 계정만 설정되어 있음으로 양호
C39: U-12 | D39: 세션 종료 시간 설정 | L39: 하 | M39: =IF(L39="상", 10, IF(L39="중", 8, IF(L39="하", 6, "-"))) -> 6 | N39: =IF(OR(O39="", O39="N/A"), "-", IF(O39="양호", 0, IF(O39="부분만족", M39/2, M39))) -> 0 | O39: 양호 | P39: =IF(O39="양호",'기준 DB'!C13&U39,IF(O39="취약",'기준 DB'!D13&U39,IF(O39="N/A",'기준 DB'!E13&U39,"-"))) -> ■ 기준 : Session Timeout이 600초(10분) 이하로 설정되어 있는 경우 "양호" ■ 현황 : 구성원이 없는 그룹(그룹에 계정이 설정되어 있으나 실제로 계정이 없음)이 없으므로 양호함 | U39: 구성원이 없는 그룹(그룹에 계정이 설정되어 있으나 실제로 계정이 없음)이 없으므로 양호함
C40: U-13 | D40: 안전한 비밀번호 암호화 알고리즘 사용 | L40: 중 | M40: =IF(L40="상", 10, IF(L40="중", 8, IF(L40="하", 6, "-"))) -> 8 | N40: =IF(OR(O40="", O40="N/A"), "-", IF(O40="양호", 0, IF(O40="부분만족", M40/2, M40))) -> 0 | O40: 양호 | P40: =IF(O40="양호",'기준 DB'!C14&U40,IF(O40="취약",'기준 DB'!D14&U40,IF(O40="N/A",'기준 DB'!E14&U40,"-"))) -> ■ 기준 : SHA-2 이상의 안전한 비밀번호 암호화 알고리즘을 사용하는 경우 "양호" ■ 현황 : 동일한 UID로 설정된 사용자 계정이 존재하지 않으므로 양호함 | U40: 동일한 UID로 설정된 사용자 계정이 존재하지 않으므로 양호함
A41: 파일 및 디렉터리 관리 | C41: U-14 | D41: root 홈, 패스 디렉터리 권한 및 패스 설정 | L41: 상 | M41: =IF(L41="상", 10, IF(L41="중", 8, IF(L41="하", 6, "-"))) -> 10 | N41: =IF(OR(O41="", O41="N/A"), "-", IF(O41="양호", 0, IF(O41="부분만족", M41/2, M41))) -> 10 | O41: 취약 | P41: =IF(O41="양호",'기준 DB'!C15&U41,IF(O41="취약",'기준 DB'!D15&U41,IF(O41="N/A",'기준 DB'!E15&U41,"-"))) -> ■ 기준 : PATH 환경변수에 “.” 이 맨 앞이나 중간에 포함되어 있는 경우 "취약" ■ 현황 : PATH 설정에 '.'이 맨 앞이나 중간에 포함되어 있지 않으므로 양호함 | U41: PATH 설정에 '.'이 맨 앞이나 중간에 포함되어 있지 않으므로 양호함
C42: U-15 | D42: 파일 및 디렉터리 소유자 설정 | L42: 상 | M42: =IF(L42="상", 10, IF(L42="중", 8, IF(L42="하", 6, "-"))) -> 10 | N42: =IF(OR(O42="", O42="N/A"), "-", IF(O42="양호", 0, IF(O42="부분만족", M42/2, M42))) -> - | O42: N/A | P42: =IF(O42="양호",'기준 DB'!C16&U42,IF(O42="취약",'기준 DB'!D16&U42,IF(O42="N/A",'기준 DB'!E16&U42,"-"))) -> ■ 기준 : 소유자가 존재하지 않은 파일 및 디렉터리가 존재하지 않는 경우"양호" 소유자가 존재하지 않은 파일 및 디렉터리가 존재하는 경우 "취약" ■ 현황 : 소유자가 존재하지 않은 파일 및 디렉터리가 존재하지 않음 | U42: 소유자가 존재하지 않은 파일 및 디렉터리가 존재하지 않음
C43: U-16 | D43: /etc/passwd 파일 소유자 및 권한 설정 | L43: 상 | M43: =IF(L43="상", 10, IF(L43="중", 8, IF(L43="하", 6, "-"))) -> 10 | N43: =IF(OR(O43="", O43="N/A"), "-", IF(O43="양호", 0, IF(O43="부분만족", M43/2, M43))) -> 0 | O43: 양호 | P43: =IF(O43="양호",'기준 DB'!C17&U43,IF(O43="취약",'기준 DB'!D17&U43,IF(O43="N/A",'기준 DB'!E17&U43,"-"))) -> ■ 기준 : /etc/passwd 파일의 소유자가 root이고, 권한이 644 이하인 경우 "양호" ■ 현황 : /etc/passwd 파일의 접근권한이 적절하게 설정되어 있어 양호함 | U43: /etc/passwd 파일의 접근권한이 적절하게 설정되어 있어 양호함
C44: U-17 | D44: 시스템 시작 스크립트 권한 설정 | L44: 상 | M44: =IF(L44="상", 10, IF(L44="중", 8, IF(L44="하", 6, "-"))) -> 10 | N44: =IF(OR(O44="", O44="N/A"), "-", IF(O44="양호", 0, IF(O44="부분만족", M44/2, M44))) -> 0 | O44: 양호 | P44: =IF(O44="양호",'기준 DB'!C18&U44,IF(O44="취약",'기준 DB'!D18&U44,IF(O44="N/A",'기준 DB'!E18&U44,"-"))) -> ■ 기준 : 시스템 시작 스크립트 파일의 소유자가 root이고, 일반 사용자의 쓰기 권한이 제거된 경우 "양호" ■ 현황 : /etc/shadow 파일의 접근권한이 과도하게 설정되어 있으므로 취약함 | U44: /etc/shadow 파일의 접근권한이 과도하게 설정되어 있으므로 취약함
C45: U-18 | D45: /etc/shadow 파일 소유자 및 권한 설정 | L45: 상 | M45: =IF(L45="상", 10, IF(L45="중", 8, IF(L45="하", 6, "-"))) -> 10 | N45: =IF(OR(O45="", O45="N/A"), "-", IF(O45="양호", 0, IF(O45="부분만족", M45/2, M45))) -> 0 | O45: 양호 | P45: =IF(O45="양호",'기준 DB'!C19&U45,IF(O45="취약",'기준 DB'!D19&U45,IF(O45="N/A",'기준 DB'!E19&U45,"-"))) -> ■ 기준 : /etc/shadow 파일의 소유자가 root이고, 권한이 400인 경우 "양호" ■ 현황 : /etc/hosts 파일의 접근권한이 과도하게 설정되어 있으므로 취약함(운영환경에 따른 판단 필요) | U45: /etc/hosts 파일의 접근권한이 과도하게 설정되어 있으므로 취약함(운영환경에 따른 판단 필요)
C46: U-19 | D46: /etc/hosts 파일 소유자 및 권한 설정 | L46: 상 | M46: =IF(L46="상", 10, IF(L46="중", 8, IF(L46="하", 6, "-"))) -> 10 | N46: =IF(OR(O46="", O46="N/A"), "-", IF(O46="양호", 0, IF(O46="부분만족", M46/2, M46))) -> 0 | O46: 양호 | P46: =IF(O46="양호",'기준 DB'!C20&U46,IF(O46="취약",'기준 DB'!D20&U46,IF(O46="N/A",'기준 DB'!E20&U46,"-"))) -> ■ 기준 : /etc/hosts 파일의 소유자가 root이고, 권한이 600인 경우 "양호" ■ 현황 : /etc/inetd.conf or /etc/xinetd.conf 파일이 존재하지 않으므로 양호함 | U46: /etc/inetd.conf or /etc/xinetd.conf 파일이 존재하지 않으므로 양호함
C47: U-20 | D47: /etc/(x)inetd.conf 파일 소유자 및 권한 설정 | L47: 상 | M47: =IF(L47="상", 10, IF(L47="중", 8, IF(L47="하", 6, "-"))) -> 10 | N47: =IF(OR(O47="", O47="N/A"), "-", IF(O47="양호", 0, IF(O47="부분만족", M47/2, M47))) -> 0 | O47: 양호 | P47: =IF(O47="양호",'기준 DB'!C21&U47,IF(O47="취약",'기준 DB'!D21&U47,IF(O47="N/A",'기준 DB'!E21&U47,"-"))) -> ■ 기준 : /etc/(x)inetd.conf 파일의 소유자가 root이고, 권한이 600인 경우 "양호" ■ 현황 : /etc/syslog.conf 파일의 접근권한이 과도하게 설정되어 있으므로 취약함 | U47: /etc/syslog.conf 파일의 접근권한이 과도하게 설정되어 있으므로 취약함
C48: U-21 | D48: /etc/(r)syslog.conf 파일 소유자 및 권한 설정 | L48: 상 | M48: =IF(L48="상", 10, IF(L48="중", 8, IF(L48="하", 6, "-"))) -> 10 | N48: =IF(OR(O48="", O48="N/A"), "-", IF(O48="양호", 0, IF(O48="부분만족", M48/2, M48))) -> 0 | O48: 양호 | P48: =IF(O48="양호",'기준 DB'!C22&U48,IF(O48="취약",'기준 DB'!D22&U48,IF(O48="N/A",'기준 DB'!E22&U48,"-"))) -> ■ 기준 : /etc/(r)syslog.conf 파일의 소유자가 root이고, 권한이 640인 경우 "양호" ■ 현황 : /etc/services 파일의 접근권한이 적절하게 설정되어 있으므로 양호함 | U48: /etc/services 파일의 접근권한이 적절하게 설정되어 있으므로 양호함
C49: U-22 | D49: /etc/services 파일 소유자 및 권한 설정 | L49: 상 | M49: =IF(L49="상", 10, IF(L49="중", 8, IF(L49="하", 6, "-"))) -> 10 | N49: =IF(OR(O49="", O49="N/A"), "-", IF(O49="양호", 0, IF(O49="부분만족", M49/2, M49))) -> 0 | O49: 양호 | P49: =IF(O49="양호",'기준 DB'!C23&U49,IF(O49="취약",'기준 DB'!D23&U49,IF(O49="N/A",'기준 DB'!E23&U49,"-"))) -> ■ 기준 : /etc/services 파일의 소유자가 root이고, 권한이 644인 경우 "양호" ■ 현황 : 주요 파일이 존재하지 않음으로 양호함 | U49: 주요 파일이 존재하지 않음으로 양호함
...

Sheet 기준 DB
B1: 점검 항목 | C1: 양호 | D1: 취약 | E1: N/A
A2: U-01 | B2: root 계정 원격 접속 제한 | C2: ■ 기준 : 원격 서비스를 사용하지 않거나, 사용 시 root 직접 접속을 차단한 경우 "양호" ■ 현황 : | D2: ■ 기준 : root 직접 접속을 허용하고 원격 서비스를 사용하는 경우 "취약" ■ 현황 : | E2: ■ 기준 : 원격 서비스를 사용하지 않거나, 사용 시 root 직접 접속을 차단한 경우 "양호" root 직접 접속을 허용하고 원격 서비스를 사용하는 경우 "취약" ■ 현황 :
A3: U-02 | B3: 비밀번호 관리정책 설정 | C3: ■ 기준 : 비밀번호 관리 정책이 설정된 경우 "양호" ■ 현황 : | D3: ■ 기준 : 비밀번호 관리 정책이 설정되지 않은 경우 "취약" ■ 현황 : | E3: ■ 기준 : 비밀번호 관리 정책이 설정된 경우 "양호" 비밀번호 관리 정책이 설정되지 않은 경우 "취약" ■ 현황 :
A4: U-03 | B4: 계정 잠금 임계값 설정 | C4: ■ 기준 : 계정 잠금 임계값이 10회 이하의 값으로 설정되어 있는 경우 "양호" ■ 현황 : | D4: ■ 기준 : 계정 잠금 임계값이 설정되어 있지 않거나, 10회 이하의 값으로 설정되지 않은 경우 "취약" ■ 현황 : | E4: ■ 기준 : 계정 잠금 임계값이 10회 이하의 값으로 설정되어 있는 경우 "양호" 계정 잠금 임계값이 설정되어 있지 않거나, 10회 이하의 값으로 설정되지 않은 경우 "취약" ■ 현황 :
A5: U-04 | B5: 비밀번호 파일 보호 | C5: ■ 기준 : 쉐도우 비밀번호를 사용하거나, 비밀번호를 암호화하여 저장하는 경우 "양호" ■ 현황 : | D5: ■ 기준 : 쉐도우 비밀번호를 사용하지 않고, 비밀번호를 암호화하여 저장하지 않는 경우 "취약" ■ 현황 : | E5: ■ 기준 : 쉐도우 비밀번호를 사용하거나, 비밀번호를 암호화하여 저장하는 경우 "양호" 쉐도우 비밀번호를 사용하지 않고, 비밀번호를 암호화하여 저장하지 않는 경우 "취약" ■ 현황 :
A6: U-05 | B6: root 이외의 UID가 '0' 금지 | C6: ■ 기준 : root 계정과 동일한 UID를 갖는 계정이 존재하지 않는 경우 "양호" ■ 현황 : | D6: ■ 기준 : root 계정과 동일한 UID를 갖는 계정이 존재하는 경우 "취약" ■ 현황 : | E6: ■ 기준 : root 계정과 동일한 UID를 갖는 계정이 존재하지 않는 경우 "양호" root 계정과 동일한 UID를 갖는 계정이 존재하는 경우 "취약" ■ 현황 :
A7: U-06 | B7: 사용자 계정 su 기능 제한 | C7: ■ 기준 : su 명령어를 특정 그룹에 속한 사용자만 사용하도록 제한된 경우 "양호" ※ 일반 사용자 계정 없이 root 계정만 사용하는 경우 su 명령어 사용 제한 불필요 ■ 현황 : | D7: ■ 기준 : su 명령어를 모든 사용자가 사용하도록 설정된 경우 "취약" ■ 현황 : | E7: ■ 기준 : su 명령어를 특정 그룹에 속한 사용자만 사용하도록 제한된 경우 "양호" su 명령어를 모든 사용자가 사용하도록 설정된 경우 "취약" ※ 일반 사용자 계정 없이 root 계정만 사용하는 경우 su 명령어 사용 제한 불필요 ■ 현황 :
A8: U-07 | B8: 불필요한 계정 제거 | C8: ■ 기준 : 불필요한 계정이 존재하지 않는 경우 "양호" ■ 현황 : | D8: ■ 기준 : 불필요한 계정이 존재하지 경우 "취약" ■ 현황 : | E8: ■ 기준 : 불필요한 계정이 존재하지 않는 경우 "양호" 불필요한 계정이 존재하지 경우 "취약" ■ 현황 :
A9: U-08 | B9: 관리자 그룹에 최소한의 계정 포함 | C9: ■ 기준 : 관리자 그룹에 불필요한 계정이 등록되어 있지 않은 경우 "양호" ■ 현황 : | D9: ■ 기준 : 관리자 그룹에 불필요한 계정이 등록되어 있는 경우 "취약" ■ 현황 : | E9: ■ 기준 : 관리자 그룹에 불필요한 계정이 등록되어 있지 않은 경우 "양호" 관리자 그룹에 불필요한 계정이 등록되어 있는 경우 "취약" ■ 현황 :
A10: U-09 | B10: 계정이 존재하지 않는 GID 금지 | C10: ■ 기준 : 시스템 관리나 운용에 불필요한 그룹이 제거된 경우 "양호" ■ 현황 : | D10: ■ 기준 : 시스템 관리나 운용에 불필요한 그룹이 존재하는 경우 "취약" ■ 현황 : | E10: ■ 기준 : 시스템 관리나 운용에 불필요한 그룹이 제거된 경우 "양호" 시스템 관리나 운용에 불필요한 그룹이 존재하는 경우 "취약" ■ 현황 :
A11: U-10 | B11: 동일한 UID 금지 | C11: ■ 기준 : 동일한 UID로 설정된 사용자 계정이 존재하지 않는 경우 "양호" ■ 현황 : | D11: ■ 기준 : 동일한 UID로 설정된 사용자 계정이 존재하는 경우 "취약" ■ 현황 : | E11: ■ 기준 : 동일한 UID로 설정된 사용자 계정이 존재하지 않는 경우 "양호" 동일한 UID로 설정된 사용자 계정이 존재하는 경우 "취약" ■ 현황 :
A12: U-11 | B12: 사용자 shell 점검 | C12: ■ 기준 : 로그인이 필요하지 않은 계정에 /bin/false(nologin) 쉘이 부여되어 있는 경우 "양호" ■ 현황 : | D12: ■ 기준 : 로그인이 필요하지 않은 계정에 /bin/false(nologin) 쉘이 부여되지 않은 경우 "취약" ■ 현황 : | E12: ■ 기준 : 로그인이 필요하지 않은 계정에 /bin/false(nologin) 쉘이 부여되어 있는 경우 "양호" 로그인이 필요하지 않은 계정에 /bin/false(nologin) 쉘이 부여되지 않은 경우 "취약" ■ 현황 :
A13: U-12 | B13: 세션 종료 시간 설정 | C13: ■ 기준 : Session Timeout이 600초(10분) 이하로 설정되어 있는 경우 "양호" ■ 현황 : | D13: ■ 기준 : Session Timeout이 600초(10분) 이하로 설정되지 않은 경우 "취약" ■ 현황 : | E13: ■ 기준 : Session Timeout이 600초(10분) 이하로 설정되어 있는 경우 "양호" Session Timeout이 600초(10분) 이하로 설정되지 않은 경우 "취약" ■ 현황 :
... A68: U-67 | B68: 로그 디렉터리 소유자 및 권한 설정 | C68: ■ 기준 : 디렉터리 내 로그 파일의 소유자가 root이고, 권한이 644 이하인 경우 "양호" ■ 현황 : | D68: ■ 기준 : 디렉터리 내 로그 파일의 소유자가 root가 아니거나, 권한이 644를 초과하는 경우 "취약" ■ 현황 : | E68: ■ 기준 : 디렉터리 내 로그 파일의 소유자가 root이고, 권한이 644 이하인 경우 "양호" 디렉터리 내 로그 파일의 소유자가 root가 아니거나, 권한이 644를 초과하는 경우 "취약" ■ 현황 :
